Workbook

Sheet PANDUAN
B1: Kalkulator Penggaris Safety Stock & Titik Tender · PKG
B2: Sumber: DATA_LEADTIME_BB.xlsx (sheet PKG) · SS, deadstock, stok posisi 4 Oktober 2026 dari dashboard CAK PRI v2beta
B4: Tujuan | C4: Menetapkan penggaris TETAP per bahan baku: bila posisi persediaan menyentuh TITIK TENDER, proses tender/pembelian harus dimulai. Angka ditinjau per periode (mis. per semester), bukan berubah harian.
B5: Tiga garis | C5: TITIK TENDER (ROP) → mulai tender. SAFETY STOCK → alarm, ada yang meleset. DEADSTOCK → lantai fisik, tidak bisa dipakai.
B6: Rumus ROP | C6: ROP = CR rata-rata × LT dipakai + SS usulan. LT dipakai = LT rata-rata (atau isian override) − pemangkasan hari persiapan.
B7: SS statistik | C7: SS = z × √( LT × sd CR² + CR² × sd LT² ), z dari tingkat layanan (95% → 1,645). Menangkap variasi konsumsi dan variasi lead time.
B8: SS maks–rata-rata | C8: SS = (LT persentil × CR persentil) − (LT rata-rata × CR rata-rata). Persentil 100% = maks murni (rumus di berkas sumber); 90% meredam pencilan.
B9: Metode dipakai | C9: Statistik · Maks–rata-rata · Terbesar dari keduanya. Pilih global di sheet Parameter, atau per bahan di sheet Penggaris (kolom pilihan).
B10: Posisi persediaan | C10: Stok gudang + kargo yang SUDAH DIKONTRAK tetapi belum tiba. Yang dibandingkan dengan ROP adalah posisi persediaan, bukan stok gudang saja, agar tidak terjadi pembelian ganda.
B11: Goal Seek | C11: TIDAK diperlukan. Semua hasil berupa rumus langsung. Pertanyaan kebalikan juga rumus langsung: tingkat layanan yang setara SS eksisting, dan perkiraan hari sampai titik tender.
B12: Cara pakai | C12: 1) Sheet Parameter: tingkat layanan, persentil, metode. 2) Sheet Penggaris: isi stok gudang terbaru dan kargo sudah kontrak (kuning). 3) Baca kolom Status. 4) Data histori di Data_LT dan Data_CR bisa ditambah; rentang rumus sudah disiapkan sampai baris kosong cadangan.
B13: Catatan data | C13: Kolom P (persiapan) di data sumber berupa asumsi tetap (7+0+25+7 atau 7+0+25+14 hari) dan L (bongkar) juga tetap, sehingga sd LT hanya mencerminkan variasi pelayaran. Ganti dengan tanggal aktual proses tender bila tersedia. Asam fosfat dan KCl flake belum punya data lead time: isi LT override atau lengkapi Data_LT.
B14: Status | C14: Indikatif untuk kajian; angka SS/ROP final mengikuti Kesepakatan PI Group setelah divalidasi Pengadaan, PPP, dan Keuangan.
B16: Arti warna
B17: contoh | C17: Isian / pilihan — boleh diubah
B18: contoh | C18: Data histori atau data dashboard (teks hitam)
B19: contoh | C19: Hasil utama
B20: contoh | C20: Teks hijau = mengambil dari sheet lain

Sheet Penggaris
A1: Penggaris Safety Stock & Titik Tender · PKG
A2: ="Tingkat layanan bawaan "&ROUND(Parameter!$C$4*100,1)&"% · persentil "&ROUND(Parameter!$C$6*100,0)&"% · metode bawaan "&Parameter!$C$7&" · pemangkasan persiapan "&Parameter!$C$9&" hari · indikatif" -> Tingkat layanan bawaan 95% · persentil 90% · metode bawaan Statistik · pemangkasan persiapan 0 hari · indikatif
B4: LEAD TIME (hari) | H4: KONSUMSI | L4: SAFETY STOCK | R4: PENGGARIS | U4: PEMBANDING | Y4: POSISI & STATUS | AD4: INFORMASI
A5: Bahan baku | B5: Kargo (n) | C5: LT rata-rata | D5: LT persentil | E5: sd LT | F5: LT override | G5: LT dipakai | H5: Bulan CR (n) | I5: CR rata-rata (t/hari) | J5: CR persentil (t/hari) | K5: sd CR | L5: Tingkat layanan | M5: z | N5: SS statistik (t) | O5: SS maks–rata-rata (t) | P5: Metode | Q5: SS USULAN (t) | R5: TITIK TENDER / ROP (t) | S5: SS usulan (hari) | T5: ROP (hari) | U5: SS eksisting (t) | V5: Selisih SS usulan − eksisting | W5: Layanan setara SS eksisting | X5: Deadstock (t) | Y5: Stok gudang (t) | Z5: Kargo sudah kontrak, belum tiba (t) | AA5: Posisi persediaan (t) | AB5: Perkiraan hari sampai ROP | AC5: STATUS | AD5: Rencana kedatangan Dalops s.d. 31 Des (t, informasi) | AE5: Turun ROP per 1 hari persiapan dipangkas (t) | AF5: Catatan data
A6: DAP | B6: =COUNT(Data_LT!$H$2:$H$21) -> 14 | C6: =IF(B6=0,"",AVERAGE(Data_LT!$H$2:$H$21)) -> 60.142857 | D6: =IF(B6=0,"",PERCENTILE(Data_LT!$H$2:$H$21,Parameter!$C$6)) -> 64 | E6: =IF(B6<2,0,STDEV(Data_LT!$H$2:$H$21)) -> 3.3479533 | G6: =IF(F6<>"",F6,IF(C6="","",MAX(0,C6-Parameter!$C$9))) -> 60.142857 | H6: =COUNT(Data_CR!$D$2:$D$19) -> 12 | I6: =IF(H6=0,"",AVERAGE(Data_CR!$D$2:$D$19)) -> 326.68653 | J6: =IF(H6=0,"",PERCENTILE(Data_CR!$D$2:$D$19,Parameter!$C$6)) -> 360.57437 | K6: =IF(H6<2,0,STDEV(Data_CR!$D$2:$D$19)) -> 42.800966 | M6: =NORMSINV(IF(L6="",Parameter!$C$4,L6)) -> 1.6448536 | N6: =IF(OR(G6="",I6=""),"",M6*SQRT(G6*K6^2+I6^2*E6^2)) -> 1880.0505 | O6: =IF(OR(G6="",I6=""),"",IF(OR(F6<>"",D6=""),MAX(0,G6*(J6-I6)),MAX(0,MAX(0,D6-Parameter!$C$9)*J6-G6*I6))) -> 3428.898 | Q6: =IF(N6="","",IF(IF(P6="",Parameter!$C$7,P6)="Statistik",N6,IF(IF(P6="",Parameter!$C$7,P6)="Maks–rata-rata",O6,MAX(N6,O6)))) -> 1880.0505 | R6: =IF(Q6="","",I6*G6+Q6) -> 21527.912 | S6: =IF(Q6="","",Q6/I6) -> 5.7549067 | T6: =IF(R6="","",R6/I6) -> 65.897764 | U6: 7000 | V6: =IF(OR(Q6="",U6=""),"",Q6-U6) -> -5119.9495 | W6: =IF(OR(U6="",N6=""),"",IF(SQRT(G6*K6^2+I6^2*E6^2)=0,"",NORMSDIST(U6/SQRT(G6*K6^2+I6^2*E6^2)))) -> 1 | X6: 1000 | Y6: 15447 | AA6: =IF(Y6="","",Y6+N(Z6)) -> 15447 | AB6: =IF(OR(AA6="",R6=""),"",(AA6-R6)/I6) -> -18.613905 | AC6: =IF(R6="","Data LT/CR belum lengkap",IF(AA6="","Isi stok gudang",IF(AA6<=R6,"MULAI TENDER / PEMBELIAN",IF(AA6<=R6*(1+Parameter!$C$10),"Siapkan tender","Belum perlu tender")))&IF(AND(Y6<>"",Q6<>""),IF(Y6<Q6," · stok gudang < SS usulan",""),"")) -> MULAI TENDER / PEMBELIAN | AD6: 40000 | AE6: =IF(I6="","",I6) -> 326.68653 | AF6: P (persiapan) tetap =7+0+25+7 hari → sd LT hanya dari pelayaran. Stok gudang terisi posisi 4 Oktober 2026 dari dashboard; perbarui.
A7: KCl powder | B7: =COUNT(Data_LT!$H$23:$H$77) -> 49 | C7: =IF(B7=0,"",AVERAGE(Data_LT!$H$23:$H$77)) -> 96.469388 | D7: =IF(B7=0,"",PERCENTILE(Data_LT!$H$23:$H$77,Parameter!$C$6)) -> 110.2 | E7: =IF(B7<2,0,STDEV(Data_LT!$H$23:$H$77)) -> 11.400113 | G7: =IF(F7<>"",F7,IF(C7="","",MAX(0,C7-Parameter!$C$9))) -> 96.469388 | H7: =COUNT(Data_CR!$D$21:$D$33) -> 7 | I7: =IF(H7=0,"",AVERAGE(Data_CR!$D$21:$D$33)) -> 1833.5725 | J7: =IF(H7=0,"",PERCENTILE(Data_CR!$D$21:$D$33,Parameter!$C$6)) -> 1989.5371 | K7: =IF(H7<2,0,STDEV(Data_CR!$D$21:$D$33)) -> 173.78234 | M7: =NORMSINV(IF(L7="",Parameter!$C$4,L7)) -> 1.6448536 | N7: =IF(OR(G7="",I7=""),"",M7*SQRT(G7*K7^2+I7^2*E7^2)) -> 34496.706 | O7: =IF(OR(G7="",I7=""),"",IF(OR(F7<>"",D7=""),MAX(0,G7*(J7-I7)),MAX(0,MAX(0,D7-Parameter!$C$9)*J7-G7*I7))) -> 42363.372 | Q7: =IF(N7="","",IF(IF(P7="",Parameter!$C$7,P7)="Statistik",N7,IF(IF(P7="",Parameter!$C$7,P7)="Maks–rata-rata",O7,MAX(N7,O7)))) -> 34496.706 | R7: =IF(Q7="","",I7*G7+Q7) -> 211380.33 | S7: =IF(Q7="","",Q7/I7) -> 18.81393 | T7: =IF(R7="","",R7/I7) -> 115.28332 | U7: 37000 | V7: =IF(OR(Q7="",U7=""),"",Q7-U7) -> -2503.2941 | W7: =IF(OR(U7="",N7=""),"",IF(SQRT(G7*K7^2+I7^2*E7^2)=0,"",NORMSDIST(U7/SQRT(G7*K7^2+I7^2*E7^2)))) -> 0.96115205 | X7: 2000 | Y7: 76969 | AA7: =IF(Y7="","",Y7+N(Z7)) -> 76969 | AB7: =IF(OR(AA7="",R7=""),"",(AA7-R7)/I7) -> -73.305704 | AC7: =IF(R7="","Data LT/CR belum lengkap",IF(AA7="","Isi stok gudang",IF(AA7<=R7,"MULAI TENDER / PEMBELIAN",IF(AA7<=R7*(1+Parameter!$C$10),"Siapkan tender","Belum perlu tender")))&IF(AND(Y7<>"",Q7<>""),IF(Y7<Q7," · stok gudang < SS usulan",""),"")) -> MULAI TENDER / PEMBELIAN | AD7: 148448 | AE7: =IF(I7="","",I7) -> 1833.5725 | AF7: P (persiapan) tetap =7+0+25+14 hari → sd LT hanya dari pelayaran. SS eksisting & stok = KCl merah + putih gabungan (Kesepakatan). Stok gudang terisi posisi 4 Oktober 2026 dari dashboard; perbarui.
A8: KCl flake | B8: =COUNT(Data_LT!$H$79:$H$84) -> 0 | C8: =IF(B8=0,"",AVERAGE(Data_LT!$H$79:$H$84)) | D8: =IF(B8=0,"",PERCENTILE(Data_LT!$H$79:$H$84,Parameter!$C$6)) | E8: =IF(B8<2,0,STDEV(Data_LT!$H$79:$H$84)) -> 0 | G8: =IF(F8<>"",F8,IF(C8="","",MAX(0,C8-Parameter!$C$9))) | H8: =COUNT(Data_CR!$D$35:$D$40) -> 0 | I8: =IF(H8=0,"",AVERAGE(Data_CR!$D$35:$D$40)) | J8: =IF(H8=0,"",PERCENTILE(Data_CR!$D$35:$D$40,Parameter!$C$6)) | K8: =IF(H8<2,0,STDEV(Data_CR!$D$35:$D$40)) -> 0 | M8: =NORMSINV(IF(L8="",Parameter!$C$4,L8)) -> 1.6448536 | N8: =IF(OR(G8="",I8=""),"",M8*SQRT(G8*K8^2+I8^2*E8^2)) | O8: =IF(OR(G8="",I8=""),"",IF(OR(F8<>"",D8=""),MAX(0,G8*(J8-I8)),MAX(0,MAX(0,D8-Parameter!$C$9)*J8-G8*I8))) | Q8: =IF(N8="","",IF(IF(P8="",Parameter!$C$7,P8)="Statistik",N8,IF(IF(P8="",Parameter!$C$7,P8)="Maks–rata-rata",O8,MAX(N8,O8)))) | R8: =IF(Q8="","",I8*G8+Q8) | S8: =IF(Q8="","",Q8/I8) | T8: =IF(R8="","",R8/I8) | V8: =IF(OR(Q8="",U8=""),"",Q8-U8) | W8: =IF(OR(U8="",N8=""),"",IF(SQRT(G8*K8^2+I8^2*E8^2)=0,"",NORMSDIST(U8/SQRT(G8*K8^2+I8^2*E8^2)))) | AA8: =IF(Y8="","",Y8+N(Z8)) | AB8: =IF(OR(AA8="",R8=""),"",(AA8-R8)/I8) | AC8: =IF(R8="","Data LT/CR belum lengkap",IF(AA8="","Isi stok gudang",IF(AA8<=R8,"MULAI TENDER / PEMBELIAN",IF(AA8<=R8*(1+Parameter!$C$10),"Siapkan tender","Belum perlu tender")))&IF(AND(Y8<>"",Q8<>""),IF(Y8<Q8," · stok gudang < SS usulan",""),"")) -> Data LT/CR belum lengkap | AE8: =IF(I8="","",I8) | AF8: Belum ada data lead time — isi LT override atau lengkapi Data_LT. Belum ada data konsumsi.
A9: ZA | B9: =COUNT(Data_LT!$H$86:$H$123) -> 32 | C9: =IF(B9=0,"",AVERAGE(Data_LT!$H$86:$H$123)) -> 68.4375 | D9: =IF(B9=0,"",PERCENTILE(Data_LT!$H$86:$H$123,Parameter!$C$6)) -> 74 | E9: =IF(B9<2,0,STDEV(Data_LT!$H$86:$H$123)) -> 3.5825518 | G9: =IF(F9<>"",F9,IF(C9="","",MAX(0,C9-Parameter!$C$9))) -> 68.4375 | H9: =COUNT(Data_CR!$D$42:$D$54) -> 7 | I9: =IF(H9=0,"",AVERAGE(Data_CR!$D$42:$D$54)) -> 2195.6244 | J9: =IF(H9=0,"",PERCENTILE(Data_CR!$D$42:$D$54,Parameter!$C$6)) -> 2411.9949 | K9: =IF(H9<2,0,STDEV(Data_CR!$D$42:$D$54)) -> 228.12893 | M9: =NORMSINV(IF(L9="",Parameter!$C$4,L9)) -> 1.6448536 | N9: =IF(OR(G9="",I9=""),"",M9*SQRT(G9*K9^2+I9^2*E9^2)) -> 13305.499 | O9: =IF(OR(G9="",I9=""),"",IF(OR(F9<>"",D9=""),MAX(0,G9*(J9-I9)),MAX(0,MAX(0,D9-Parameter!$C$9)*J9-G9*I9))) -> 28224.583 | Q9: =IF(N9="","",IF(IF(P9="",Parameter!$C$7,P9)="Statistik",N9,IF(IF(P9="",Parameter!$C$7,P9)="Maks–rata-rata",O9,MAX(N9,O9)))) -> 13305.499 | R9: =IF(Q9="","",I9*G9+Q9) -> 163568.54 | S9: =IF(Q9="","",Q9/I9) -> 6.0600072 | T9: =IF(R9="","",R9/I9) -> 74.497507 | V9: =IF(OR(Q9="",U9=""),"",Q9-U9) | W9: =IF(OR(U9="",N9=""),"",IF(SQRT(G9*K9^2+I9^2*E9^2)=0,"",NORMSDIST(U9/SQRT(G9*K9^2+I9^2*E9^2)))) | AA9: =IF(Y9="","",Y9+N(Z9)) | AB9: =IF(OR(AA9="",R9=""),"",(AA9-R9)/I9) | AC9: =IF(R9="","Data LT/CR belum lengkap",IF(AA9="","Isi stok gudang",IF(AA9<=R9,"MULAI TENDER / PEMBELIAN",IF(AA9<=R9*(1+Parameter!$C$10),"Siapkan tender","Belum perlu tender")))&IF(AND(Y9<>"",Q9<>""),IF(Y9<Q9," · stok gudang < SS usulan",""),"")) -> Isi stok gudang | AE9: =IF(I9="","",I9) -> 2195.6244 | AF9: P (persiapan) tetap =7+0+25+14 hari → sd LT hanya dari pelayaran.
A10: Batuan fosfat (RP) | B10: =COUNT(Data_LT!$H$125:$H$171) -> 41 | C10: =IF(B10=0,"",AVERAGE(Data_LT!$H$125:$H$171)) -> 85.414634 | D10: =IF(B10=0,"",PERCENTILE(Data_LT!$H$125:$H$171,Parameter!$C$6)) -> 94 | E10: =IF(B10<2,0,STDEV(Data_LT!$H$125:$H$171)) -> 7.3074469 | G10: =IF(F10<>"",F10,IF(C10="","",MAX(0,C10-Parameter!$C$9))) -> 85.414634 | H10: =COUNT(Data_CR!$D$56:$D$73) -> 12 | I10: =IF(H10=0,"",AVERAGE(Data_CR!$D$56:$D$73)) -> 1792.0307 | J10: =IF(H10=0,"",PERCENTILE(Data_CR!$D$56:$D$73,Parameter!$C$6)) -> 2688.3506 | K10: =IF(H10<2,0,STDEV(Data_CR!$D$56:$D$73)) -> 721.73876 | M10: =NORMSINV(IF(L10="",Parameter!$C$4,L10)) -> 1.6448536 | N10: =IF(OR(G10="",I10=""),"",M10*SQRT(G10*K10^2+I10^2*E10^2)) -> 24172.998 | O10: =IF(OR(G10="",I10=""),"",IF(OR(F10<>"",D10=""),MAX(0,G10*(J10-I10)),MAX(0,MAX(0,D10-Parameter!$C$9)*J10-G10*I10))) -> 99639.317 | Q10: =IF(N10="","",IF(IF(P10="",Parameter!$C$7,P10)="Statistik",N10,IF(IF(P10="",Parameter!$C$7,P10)="Maks–rata-rata",O10,MAX(N10,O10)))) -> 24172.998 | R10: =IF(Q10="","",I10*G10+Q10) -> 177238.64 | S10: =IF(Q10="","",Q10/I10) -> 13.489166 | T10: =IF(R10="","",R10/I10) -> 98.9038 | U10: 100000 | V10: =IF(OR(Q10="",U10=""),"",Q10-U10) -> -75827.002 | W10: =IF(OR(U10="",N10=""),"",IF(SQRT(G10*K10^2+I10^2*E10^2)=0,"",NORMSDIST(U10/SQRT(G10*K10^2+I10^2*E10^2)))) -> 1 | X10: 20000 | Y10: 145829 | AA10: =IF(Y10="","",Y10+N(Z10)) -> 145829 | AB10: =IF(OR(AA10="",R10=""),"",(AA10-R10)/I10) -> -17.527402 | AC10: =IF(R10="","Data LT/CR belum lengkap",IF(AA10="","Isi stok gudang",IF(AA10<=R10,"MULAI TENDER / PEMBELIAN",IF(AA10<=R10*(1+Parameter!$C$10),"Siapkan tender","Belum perlu tender")))&IF(AND(Y10<>"",Q10<>""),IF(Y10<Q10," · stok gudang < SS usulan",""),"")) -> MULAI TENDER / PEMBELIAN | AD10: 120000 | AE10: =IF(I10="","",I10) -> 1792.0307 | AF10: P (persiapan) tetap =7+0+25+14 hari → sd LT hanya dari pelayaran. SS eksisting: tetap 100.000 ton dengan pertimbangan masih berlangsungnya konflik Timur Tengah. Stok gudang terisi posisi 4 Oktober 2026 dari dashboard; perbarui.
A11: Asam sulfat (SA) | B11: =COUNT(Data_LT!$H$173:$H$200) -> 22 | C11: =IF(B11=0,"",AVERAGE(Data_LT!$H$173:$H$200)) -> 53.136364 | D11: =IF(B11=0,"",PERCENTILE(Data_LT!$H$173:$H$200,Parameter!$C$6)) -> 57 | E11: =IF(B11<2,0,STDEV(Data_LT!$H$173:$H$200)) -> 3.3988157 | G11: =IF(F11<>"",F11,IF(C11="","",MAX(0,C11-Parameter!$C$9))) -> 53.136364 | H11: =COUNT(Data_CR!$D$75:$D$90) -> 10 | I11: =IF(H11=0,"",AVERAGE(Data_CR!$D$75:$D$90)) -> 866.47627 | J11: =IF(H11=0,"",PERCENTILE(Data_CR!$D$75:$D$90,Parameter!$C$6)) -> 1552.8234 | K11: =IF(H11<2,0,STDEV(Data_CR!$D$75:$D$90)) -> 556.56758 | M11: =NORMSINV(IF(L11="",Parameter!$C$4,L11)) -> 1.6448536 | N11: =IF(OR(G11="",I11=""),"",M11*SQRT(G11*K11^2+I11^2*E11^2)) -> 8246.0995 | O11: =IF(OR(G11="",I11=""),"",IF(OR(F11<>"",D11=""),MAX(0,G11*(J11-I11)),MAX(0,MAX(0,D11-Parameter!$C$9)*J11-G11*I11))) -> 42469.533 | Q11: =IF(N11="","",IF(IF(P11="",Parameter!$C$7,P11)="Statistik",N11,IF(IF(P11="",Parameter!$C$7,P11)="Maks–rata-rata",O11,MAX(N11,O11)))) -> 8246.0995 | R11: =IF(Q11="","",I11*G11+Q11) -> 54287.498 | S11: =IF(Q11="","",Q11/I11) -> 9.5168209 | T11: =IF(R11="","",R11/I11) -> 62.653185 | U11: 20000 | V11: =IF(OR(Q11="",U11=""),"",Q11-U11) -> -11753.9 | W11: =IF(OR(U11="",N11=""),"",IF(SQRT(G11*K11^2+I11^2*E11^2)=0,"",NORMSDIST(U11/SQRT(G11*K11^2+I11^2*E11^2)))) -> 0.99996688 | X11: 5000 | Y11: 34723 | AA11: =IF(Y11="","",Y11+N(Z11)) -> 34723 | AB11: =IF(OR(AA11="",R11=""),"",(AA11-R11)/I11) -> -22.579381 | AC11: =IF(R11="","Data LT/CR belum lengkap",IF(AA11="","Isi stok gudang",IF(AA11<=R11,"MULAI TENDER / PEMBELIAN",IF(AA11<=R11*(1+Parameter!$C$10),"Siapkan tender","Belum perlu tender")))&IF(AND(Y11<>"",Q11<>""),IF(Y11<Q11," · stok gudang < SS usulan",""),"")) -> MULAI TENDER / PEMBELIAN | AD11: 0 | AE11: =IF(I11="","",I11) -> 866.47627 | AF11: P (persiapan) tetap =7+0+25+7 hari → sd LT hanya dari pelayaran. Stok gudang terisi posisi 4 Oktober 2026 dari dashboard; perbarui.
A12: Asam fosfat (PA) | B12: =COUNT(Data_LT!$H$202:$H$207) -> 0 | C12: =IF(B12=0,"",AVERAGE(Data_LT!$H$202:$H$207)) | D12: =IF(B12=0,"",PERCENTILE(Data_LT!$H$202:$H$207,Parameter!$C$6)) | E12: =IF(B12<2,0,STDEV(Data_LT!$H$202:$H$207)) -> 0 | G12: =IF(F12<>"",F12,IF(C12="","",MAX(0,C12-Parameter!$C$9))) | H12: =COUNT(Data_CR!$D$92:$D$109) -> 12 | I12: =IF(H12=0,"",AVERAGE(Data_CR!$D$92:$D$109)) -> 1795.4606 | J12: =IF(H12=0,"",PERCENTILE(Data_CR!$D$92:$D$109,Parameter!$C$6)) -> 2025.4065 | K12: =IF(H12<2,0,STDEV(Data_CR!$D$92:$D$109)) -> 223.29459 | M12: =NORMSINV(IF(L12="",Parameter!$C$4,L12)) -> 1.6448536 | N12: =IF(OR(G12="",I12=""),"",M12*SQRT(G12*K12^2+I12^2*E12^2)) | O12: =IF(OR(G12="",I12=""),"",IF(OR(F12<>"",D12=""),MAX(0,G12*(J12-I12)),MAX(0,MAX(0,D12-Parameter!$C$9)*J12-G12*I12))) | Q12: =IF(N12="","",IF(IF(P12="",Parameter!$C$7,P12)="Statistik",N12,IF(IF(P12="",Parameter!$C$7,P12)="Maks–rata-rata",O12,MAX(N12,O12)))) | R12: =IF(Q12="","",I12*G12+Q12) | S12: =IF(Q12="","",Q12/I12) | T12: =IF(R12="","",R12/I12) | U12: 20000 | V12: =IF(OR(Q12="",U12=""),"",Q12-U12) | W12: =IF(OR(U12="",N12=""),"",IF(SQRT(G12*K12^2+I12^2*E12^2)=0,"",NORMSDIST(U12/SQRT(G12*K12^2+I12^2*E12^2)))) | X12: 6000 | Y12: 32758 | AA12: =IF(Y12="","",Y12+N(Z12)) -> 32758 | AB12: =IF(OR(AA12="",R12=""),"",(AA12-R12)/I12) | AC12: =IF(R12="","Data LT/CR belum lengkap",IF(AA12="","Isi stok gudang",IF(AA12<=R12,"MULAI TENDER / PEMBELIAN",IF(AA12<=R12*(1+Parameter!$C$10),"Siapkan tender","Belum perlu tender")))&IF(AND(Y12<>"",Q12<>""),IF(Y12<Q12," · stok gudang < SS usulan",""),"")) -> Data LT/CR belum lengkap | AD12: 20000 | AE12: =IF(I12="","",I12) -> 1795.4606 | AF12: Belum ada data lead time — isi LT override atau lengkapi Data_LT. Stok gudang terisi posisi 4 Oktober 2026 dari dashboard; perbarui.
A13: Belerang | B13: =COUNT(Data_LT!$H$209:$H$237) -> 23 | C13: =IF(B13=0,"",AVERAGE(Data_LT!$H$209:$H$237)) -> 68.173913 | D13: =IF(B13=0,"",PERCENTILE(Data_LT!$H$209:$H$237,Parameter!$C$6)) -> 69 | E13: =IF(B13<2,0,STDEV(Data_LT!$H$209:$H$237)) -> 1.4663552 | G13: =IF(F13<>"",F13,IF(C13="","",MAX(0,C13-Parameter!$C$9))) -> 68.173913 | H13: =COUNT(Data_CR!$D$111:$D$125) -> 9 | I13: =IF(H13=0,"",AVERAGE(Data_CR!$D$111:$D$125)) -> 494.3923 | J13: =IF(H13=0,"",PERCENTILE(Data_CR!$D$111:$D$125,Parameter!$C$6)) -> 540.52795 | K13: =IF(H13<2,0,STDEV(Data_CR!$D$111:$D$125)) -> 53.567704 | M13: =NORMSINV(IF(L13="",Parameter!$C$4,L13)) -> 1.6448536 | N13: =IF(OR(G13="",I13=""),"",M13*SQRT(G13*K13^2+I13^2*E13^2)) -> 1396.852 | O13: =IF(OR(G13="",I13=""),"",IF(OR(F13<>"",D13=""),MAX(0,G13*(J13-I13)),MAX(0,MAX(0,D13-Parameter!$C$9)*J13-G13*I13))) -> 3591.7709 | Q13: =IF(N13="","",IF(IF(P13="",Parameter!$C$7,P13)="Statistik",N13,IF(IF(P13="",Parameter!$C$7,P13)="Maks–rata-rata",O13,MAX(N13,O13)))) -> 1396.852 | R13: =IF(Q13="","",I13*G13+Q13) -> 35101.509 | S13: =IF(Q13="","",Q13/I13) -> 2.8253919 | T13: =IF(R13="","",R13/I13) -> 70.999305 | U13: 10000 | V13: =IF(OR(Q13="",U13=""),"",Q13-U13) -> -8603.148 | W13: =IF(OR(U13="",N13=""),"",IF(SQRT(G13*K13^2+I13^2*E13^2)=0,"",NORMSDIST(U13/SQRT(G13*K13^2+I13^2*E13^2)))) -> 1 | X13: 5000 | Y13: 13984 | AA13: =IF(Y13="","",Y13+N(Z13)) -> 13984 | AB13: =IF(OR(AA13="",R13=""),"",(AA13-R13)/I13) -> -42.714075 | AC13: =IF(R13="","Data LT/CR belum lengkap",IF(AA13="","Isi stok gudang",IF(AA13<=R13,"MULAI TENDER / PEMBELIAN",IF(AA13<=R13*(1+Parameter!$C$10),"Siapkan tender","Belum perlu tender")))&IF(AND(Y13<>"",Q13<>""),IF(Y13<Q13," · stok gudang < SS usulan",""),"")) -> MULAI TENDER / PEMBELIAN | AD13: 62789 | AE13: =IF(I13="","",I13) -> 494.3923 | AF13: P (persiapan) tetap =7+0+25+7 hari → sd LT hanya dari pelayaran. SS eksisting: terdiri atas safety stock 5.000 ton dan deadstock 5.000 ton. Stok gudang terisi posisi 4 Oktober 2026 dari dashboard; perbarui.
A15: Cara baca: bila POSISI PERSEDIAAN ≤ TITIK TENDER → proses tender/pembelian dimulai. Bila stok gudang < SS usulan → alarm: ada yang meleset dari rencana.
A16: Stok gudang terisi posisi data dashboard; kolom kargo sudah kontrak sengaja dikosongkan karena rencana kedatangan Dalops belum tentu sudah dikontrak (lihat kolom AD sebagai pembanding).
A17: SS eksisting = Kesepakatan Safety Stock Bahan Baku PI Group (dashboard v2beta). ZA dan KCl flake belum punya angka eksisting.
A18: Indikatif untuk kajian. Penggaris final ditetapkan setelah validasi Pengadaan (lead time aktual), PPP (konsumsi), Keuangan (biaya simpan) dan disepakati di forum PI Group.

Sheet Parameter
B1: Parameter global
B3: Parameter | C3: Nilai | D3: Satuan | E3: Keterangan
B4: Tingkat layanan (bawaan) | C4: 0.95 | D4: % | E4: Peluang tidak kehabisan stok selama satu siklus pengadaan. 95% → z = 1,645.
B5: Nilai z | C5: =NORMSINV(C4) -> 1.6448536 | E5: Otomatis dari tingkat layanan.
B6: Persentil untuk "maks" (metode maks–rata-rata) | C6: 0.9 | D6: % | E6: 100% = maks murni (seperti berkas sumber). 90% disarankan agar satu bulan ekstrem tidak melambungkan SS.
B7: Metode SS bawaan | C7: Statistik | E7: Statistik · Maks–rata-rata · Terbesar
B8: Hari per bulan (konversi CR bulanan → harian) | C8: 30 | D8: hari | E8: Sama dengan berkas sumber (CR hari = CR bulan / 30).
B9: Pemangkasan hari persiapan (semua bahan) | C9: 0 | D9: hari | E9: Uji dampak mempercepat proses tender. Mengurangi LT semua bahan.
B10: Batas "siapkan tender" di atas ROP | C10: 0.1 | D10: % | E10: Status kuning bila posisi persediaan ≤ ROP × (1 + nilai ini).

Sheet Data_LT
A1: Bahan | B1: No | C1: Asal | D1: P · persiapan | E1: S · pelayaran | F1: L · muat/bongkar | G1: C · kongesti | H1: LT (hari) | J1: Sumber: DATA_LEADTIME_BB.xlsx, sheet PKG. Kolom P memakai rumus asli berkas (komponen hari persiapan). Baris kuning = cadangan untuk kargo baru.
A2: DAP | B2: 1 | C2: China | D2: =7+0+25+7 -> 39 | E2: 15 | F2: 10 | H2: =IF(COUNT(D2:G2)=0,"",SUM(D2:G2)) -> 64
A3: DAP | B3: 2 | C3: Laos | D3: =7+0+25+7 -> 39 | E3: 7 | F3: 10 | H3: =IF(COUNT(D3:G3)=0,"",SUM(D3:G3)) -> 56
A4: DAP | B4: 3 | C4: China | D4: =7+0+25+7 -> 39 | E4: 12 | F4: 10 | H4: =IF(COUNT(D4:G4)=0,"",SUM(D4:G4)) -> 61
A5: DAP | B5: 4 | C5: Vietnam | D5: =7+0+25+7 -> 39 | E5: 7 | F5: 10 | H5: =IF(COUNT(D5:G5)=0,"",SUM(D5:G5)) -> 56
A6: DAP | B6: 5 | C6: China | D6: =7+0+25+7 -> 39 | E6: 15 | F6: 10 | H6: =IF(COUNT(D6:G6)=0,"",SUM(D6:G6)) -> 64
A7: DAP | B7: 6 | C7: China | D7: =7+0+25+7 -> 39 | E7: 15 | F7: 10 | H7: =IF(COUNT(D7:G7)=0,"",SUM(D7:G7)) -> 64
A8: DAP | B8: 7 | C8: China | D8: =7+0+25+7 -> 39 | E8: 14 | F8: 10 | H8: =IF(COUNT(D8:G8)=0,"",SUM(D8:G8)) -> 63
A9: DAP | B9: 8 | C9: China | D9: =7+0+25+7 -> 39 | E9: 10 | F9: 10 | H9: =IF(COUNT(D9:G9)=0,"",SUM(D9:G9)) -> 59
A10: DAP | B10: 9 | C10: Vietnam | D10: =7+0+25+7 -> 39 | E10: 7 | F10: 10 | H10: =IF(COUNT(D10:G10)=0,"",SUM(D10:G10)) -> 56
A11: DAP | B11: 10 | C11: Vietnam | D11: =7+0+25+7 -> 39 | E11: 7 | F11: 10 | H11: =IF(COUNT(D11:G11)=0,"",SUM(D11:G11)) -> 56
A12: DAP | B12: 11 | C12: China | D12: =7+0+25+7 -> 39 | E12: 14 | F12: 10 | H12: =IF(COUNT(D12:G12)=0,"",SUM(D12:G12)) -> 63
A13: DAP | B13: 12 | C13: China | D13: =7+0+25+7 -> 39 | E13: 9 | F13: 10 | H13: =IF(COUNT(D13:G13)=0,"",SUM(D13:G13)) -> 58
... A15: DAP | B15: 14 | C15: China | D15: =7+0+25+7 -> 39 | E15: 10 | F15: 10 | H15: =IF(COUNT(D15:G15)=0,"",SUM(D15:G15)) -> 59
A16: DAP | H16: =IF(COUNT(D16:G16)=0,"",SUM(D16:G16))
A17: DAP | H17: =IF(COUNT(D17:G17)=0,"",SUM(D17:G17))
A18: DAP | H18: =IF(COUNT(D18:G18)=0,"",SUM(D18:G18))
A19: DAP | H19: =IF(COUNT(D19:G19)=0,"",SUM(D19:G19))
A20: DAP | H20: =IF(COUNT(D20:G20)=0,"",SUM(D20:G20))
A21: DAP | H21: =IF(COUNT(D21:G21)=0,"",SUM(D21:G21))
A23: KCl powder | B23: 1 | C23: Belarusia | D23: =7+0+25+14 -> 46 | E23: 54 | F23: 10 | H23: =IF(COUNT(D23:G23)=0,"",SUM(D23:G23)) -> 110
A24: KCl powder | B24: 2 | C24: Jordan | D24: =7+0+25+14 -> 46 | E24: 28 | F24: 10 | H24: =IF(COUNT(D24:G24)=0,"",SUM(D24:G24)) -> 84
A25: KCl powder | B25: 3 | C25: Jordan | D25: =7+0+25+14 -> 46 | E25: 18 | F25: 10 | H25: =IF(COUNT(D25:G25)=0,"",SUM(D25:G25)) -> 74
A26: KCl powder | B26: 4 | C26: Jordan | D26: =7+0+25+14 -> 46 | E26: 22 | F26: 10 | H26: =IF(COUNT(D26:G26)=0,"",SUM(D26:G26)) -> 78
A27: KCl powder | B27: 5 | C27: Russia | D27: =7+0+25+14 -> 46 | E27: 31 | F27: 10 | H27: =IF(COUNT(D27:G27)=0,"",SUM(D27:G27)) -> 87
A28: KCl powder | B28: 6 | C28: Russia | D28: =7+0+25+14 -> 46 | E28: 32 | F28: 10 | H28: =IF(COUNT(D28:G28)=0,"",SUM(D28:G28)) -> 88
A29: KCl powder | B29: 7 | C29: Russia | D29: =7+0+25+14 -> 46 | E29: 37 | F29: 10 | H29: =IF(COUNT(D29:G29)=0,"",SUM(D29:G29)) -> 93
A30: KCl powder | B30: 8 | C30: Russia | D30: =7+0+25+14 -> 46 | E30: 49 | F30: 10 | H30: =IF(COUNT(D30:G30)=0,"",SUM(D30:G30)) -> 105
A31: KCl powder | B31: 9 | C31: Russia | D31: =7+0+25+14 -> 46 | E31: 40 | F31: 10 | H31: =IF(COUNT(D31:G31)=0,"",SUM(D31:G31)) -> 96
A32: KCl powder | B32: 10 | C32: Russia | D32: =7+0+25+14 -> 46 | E32: 41 | F32: 10 | H32: =IF(COUNT(D32:G32)=0,"",SUM(D32:G32)) -> 97
A33: KCl powder | B33: 11 | C33: Belarusia | D33: =7+0+25+14 -> 46 | E33: 42 | F33: 10 | H33: =IF(COUNT(D33:G33)=0,"",SUM(D33:G33)) -> 98
A34: KCl powder | B34: 12 | C34: Jordan | D34: =7+0+25+14 -> 46 | E34: 27 | F34: 10 | H34: =IF(COUNT(D34:G34)=0,"",SUM(D34:G34)) -> 83
... A71: KCl powder | B71: 49 | C71: Jordan | D71: =7+0+25+14 -> 46 | E71: 25 | F71: 10 | H71: =IF(COUNT(D71:G71)=0,"",SUM(D71:G71)) -> 81
A72: KCl powder | H72: =IF(COUNT(D72:G72)=0,"",SUM(D72:G72))
A73: KCl powder | H73: =IF(COUNT(D73:G73)=0,"",SUM(D73:G73))
A74: KCl powder | H74: =IF(COUNT(D74:G74)=0,"",SUM(D74:G74))
A75: KCl powder | H75: =IF(COUNT(D75:G75)=0,"",SUM(D75:G75))
A76: KCl powder | H76: =IF(COUNT(D76:G76)=0,"",SUM(D76:G76))
A77: KCl powder | H77: =IF(COUNT(D77:G77)=0,"",SUM(D77:G77))
A79: KCl flake | H79: =IF(COUNT(D79:G79)=0,"",SUM(D79:G79))
...

Sheet Data_CR
A1: Bahan | B1: Bulan ke | C1: CR bulan (t) | D1: CR hari (t) | F1: Sumber: DATA_LEADTIME_BB.xlsx, sheet PKG, kolom Cons. Rate (month). Baris kuning = cadangan bulan baru.
A2: DAP | B2: 1 | C2: 9295.184 | D2: =IF(C2="","",C2/Parameter!$C$8) -> 309.83947
A3: DAP | B3: 2 | C3: 10314.188 | D3: =IF(C3="","",C3/Parameter!$C$8) -> 343.80627
A4: DAP | B4: 3 | C4: 7067.51 | D4: =IF(C4="","",C4/Parameter!$C$8) -> 235.58367
A5: DAP | B5: 4 | C5: 9061.582 | D5: =IF(C5="","",C5/Parameter!$C$8) -> 302.05273
A6: DAP | B6: 5 | C6: 9478.231 | D6: =IF(C6="","",C6/Parameter!$C$8) -> 315.94103
A7: DAP | B7: 6 | C7: 9158.077 | D7: =IF(C7="","",C7/Parameter!$C$8) -> 305.26923
A8: DAP | B8: 7 | C8: 12378.357 | D8: =IF(C8="","",C8/Parameter!$C$8) -> 412.6119
A9: DAP | B9: 8 | C9: 10420.958 | D9: =IF(C9="","",C9/Parameter!$C$8) -> 347.36527
A10: DAP | B10: 9 | C10: 9226.875 | D10: =IF(C10="","",C10/Parameter!$C$8) -> 307.5625
A11: DAP | B11: 10 | C11: 10841.23 | D11: =IF(C11="","",C11/Parameter!$C$8) -> 361.37433
A12: DAP | B12: 11 | C12: 9763.72 | D12: =IF(C12="","",C12/Parameter!$C$8) -> 325.45733
A13: DAP | B13: 12 | C13: 10601.24 | D13: =IF(C13="","",C13/Parameter!$C$8) -> 353.37467
A14: DAP | D14: =IF(C14="","",C14/Parameter!$C$8)
A15: DAP | D15: =IF(C15="","",C15/Parameter!$C$8)
A16: DAP | D16: =IF(C16="","",C16/Parameter!$C$8)
A17: DAP | D17: =IF(C17="","",C17/Parameter!$C$8)
A18: DAP | D18: =IF(C18="","",C18/Parameter!$C$8)
A19: DAP | D19: =IF(C19="","",C19/Parameter!$C$8)
A21: KCl powder | B21: 1 | C21: 55738.541 | D21: =IF(C21="","",C21/Parameter!$C$8) -> 1857.9514
A22: KCl powder | B22: 2 | C22: 58749.507 | D22: =IF(C22="","",C22/Parameter!$C$8) -> 1958.3169
A23: KCl powder | B23: 3 | C23: 55700.005 | D23: =IF(C23="","",C23/Parameter!$C$8) -> 1856.6668
A24: KCl powder | B24: 4 | C24: 50873.094 | D24: =IF(C24="","",C24/Parameter!$C$8) -> 1695.7698
A25: KCl powder | B25: 5 | C25: 45590.83 | D25: =IF(C25="","",C25/Parameter!$C$8) -> 1519.6943
A26: KCl powder | B26: 6 | C26: 57307.233 | D26: =IF(C26="","",C26/Parameter!$C$8) -> 1910.2411
A27: KCl powder | B27: 7 | C27: 61091.025 | D27: =IF(C27="","",C27/Parameter!$C$8) -> 2036.3675
A28: KCl powder | D28: =IF(C28="","",C28/Parameter!$C$8)
A29: KCl powder | D29: =IF(C29="","",C29/Parameter!$C$8)
A30: KCl powder | D30: =IF(C30="","",C30/Parameter!$C$8)
A31: KCl powder | D31: =IF(C31="","",C31/Parameter!$C$8)
A32: KCl powder | D32: =IF(C32="","",C32/Parameter!$C$8)
A33: KCl powder | D33: =IF(C33="","",C33/Parameter!$C$8)
A35: KCl flake | D35: =IF(C35="","",C35/Parameter!$C$8)
A36: KCl flake | D36: =IF(C36="","",C36/Parameter!$C$8)
A37: KCl flake | D37: =IF(C37="","",C37/Parameter!$C$8)
A38: KCl flake | D38: =IF(C38="","",C38/Parameter!$C$8)
A39: KCl flake | D39: =IF(C39="","",C39/Parameter!$C$8)
A40: KCl flake | D40: =IF(C40="","",C40/Parameter!$C$8)
A42: ZA | B42: 1 | C42: 53340.369 | D42: =IF(C42="","",C42/Parameter!$C$8) -> 1778.0123
A43: ZA | B43: 2 | C43: 64190.058 | D43: =IF(C43="","",C43/Parameter!$C$8) -> 2139.6686
...
