Workbook

Sheet PANDUAN
A1: Log Kargo & Lead Time Bahan Baku — PT Petrokimia Gresik
A2: Format baru pengganti DATA_LEADTIME_BB (sheet PKG): satu baris = satu kapal/kargo, dengan tanggal aktual setiap tahap.
B4: TUJUAN
C5: Di DATA_LEADTIME_BB, hanya Sailing (S) yang berupa data aktual. Preparation (P) diisi tetap 39/46 hari, Loading (L) tetap per bahan, Congestion (C) kosong. Akibatnya variasi lead time dari tender, laycan, dan antrean dermaga tidak terukur, padahal itu sumber risiko terbesar. Format ini mencatat TANGGAL setiap tahap sehingga P, L, S, C dihitung otomatis dan siap dipakai untuk King's/Monte Carlo.
B6: RANTAI TANGGAL
C7: ① Tender dibuka → ② Kontrak/PO → ③ Mulai muat → ④ Berangkat (ETS) → ⑤ Tiba di Gresik (ETA/NOR) → ⑥ Sandar → ⑦ Selesai bongkar
C8: P1 Tender = ②−① · P2 Persiapan pemasok = ③−② · P Preparation = ③−①
C9: L1 Muat = ④−③ · S Sailing = ⑤−④ · C Antrean/kongesti = ⑥−⑤ · L2 Bongkar = ⑦−⑥
C10: LT total = ⑦−① (= P + L1 + S + C + L2) · Telat laycan = ④ − laycan akhir (positif = berangkat sesudah jendela laycan)
B11: ISI DARI MANA
C12: Sheet Log_Kargo sudah terisi 213 kargo PKG 2022–2024 dari sheet "LT History" (komoditi, pemasok, kapal, pelabuhan, kuantum B/L, laycan, ETS, ETA, status). Laycan berupa teks (mis. "22-24 Juni 23") sudah diurai menjadi laycan awal & akhir; teks aslinya tetap di kolom "Laycan (teks asli)" untuk dicek.
C13: Yang MASIH PERLU DIISI tim: ① Tender dibuka, ② Kontrak/PO, ③ Mulai muat, ⑥ Sandar, ⑦ Selesai bongkar, kuantum kontrak, penyebab terlambat. Sumber: dokumen pengadaan (PR/RFQ/kontrak), SOF (Statement of Facts) kapal, laporan bongkar pelabuhan.
C14: Kargo baru (2025 dst.) ditambahkan di baris kosong berikutnya; rumus sudah tersedia sampai baris 1004.
B15: KODE WARNA
C16: Kuning = sel isian. Abu-abu = rumus (jangan diketik). Kolom "Cek" memberi tanda bila urutan tanggal tidak wajar.
B17: SHEET
C18: Log_Kargo — data utama per kargo (inilah masukan Monte Carlo).
C19: Data_CR — konsumsi aktual per bulan per bahan (isi dari laporan pemakaian bahan baku).
C20: Statistik — n, rata-rata, maks, simpangan baku, persentil 90 tiap komponen per bahan + status kesiapan Monte Carlo.
C21: Data_Lama — salinan apa adanya DATA_LEADTIME_BB sheet PKG (durasi P/S/L/C & konsumsi) sebagai pembanding.
B22: CATATAN
C23: Nama komoditi diseragamkan ke kolom Bahan (mis. "KCL 1 st", "Buyer Option" → KCL; "DAP 64 2nd" → DAP; "RP MG/HG" → RP). MAP dan SN (natrium nitrat, kontainer) masuk LAINNYA. Spesifikasi asli tetap di kolom Komoditi.
C24: ETS/ETA di LT History dianggap tanggal aktual bila status Selesai. Untuk kargo berstatus Nominasi kapal / Dalam pelayaran, tanggal tersebut masih rencana — perbarui setelah kargo selesai.
C25: Simpangan baku konsumsi harian di Statistik = simpangan baku bulanan ÷ √30 (bukan ÷ 30 seperti di file lama), dengan asumsi konsumsi antar hari saling bebas. Untuk perhitungan SS, lebih aman memakai satuan bulanan langsung.
B26: RINGKASAN OTOMATIS
B27: Jumlah kargo tercatat | C27: =COUNTA(Log_Kargo!B5:B1004) -> 213
B28: Kargo dengan tanggal berangkat & tiba (S aktual) | C28: =SUMPRODUCT((Log_Kargo!B5:B1004<>"")*ISNUMBER(Log_Kargo!Q5:Q1004)*ISNUMBER(Log_Kargo!R5:R1004)) -> 168
B29: Kargo dengan tanggal tender & mulai muat (P aktual) | C29: =SUMPRODUCT((Log_Kargo!B5:B1004<>"")*ISNUMBER(Log_Kargo!AC5:AC1004)) -> 0
B30: Kargo dengan rantai lengkap 7/7 | C30: =COUNTIF(Log_Kargo!AJ5:AJ1004,"7/7") -> 0
B31: Baris dengan tanda di kolom Cek | C31: =SUMPRODUCT((Log_Kargo!B5:B1004<>"")*(Log_Kargo!AK5:AK1004<>"OK")) -> 16

Sheet Log_Kargo
A1: Log Kargo Bahan Baku PKG
A2: Satu baris = satu kargo. Kuning = isian · abu-abu = rumus · baris 5–1004.
A3: IDENTITAS KARGO | L3: TANGGAL (isi tanggal aktual) | U3: KETERANGAN | AA3: DURASI (hari) — otomatis
A4: No | B4: Bahan | C4: Komoditi / spesifikasi | D4: Tahun | E4: Negara asal | F4: Pelabuhan muat | G4: Pelabuhan bongkar | H4: Pemasok | I4: Kapal | J4: Kuantum kontrak (t) | K4: Kuantum B/L aktual (t) | L4: ① Tender dibuka | M4: ② Kontrak / PO | N4: Laycan awal (rencana) | O4: Laycan akhir (rencana) | P4: ③ Mulai muat | Q4: ④ Berangkat (ETS aktual) | R4: ⑤ Tiba Gresik (ETA / NOR) | S4: ⑥ Sandar | T4: ⑦ Selesai bongkar | U4: Status | V4: Penyebab terlambat | W4: Catatan | X4: Laycan (teks asli) | Y4: Sailing tercatat (hari) | Z4: Sumber data | AA4: P1 Tender (②−①) | AB4: P2 Persiapan (③−②) | AC4: P Preparation (③−①) | AD4: L1 Muat (④−③) | AE4: S Sailing (⑤−④) | AF4: C Antrean (⑥−⑤) | AG4: L2 Bongkar (⑦−⑥) | AH4: LT total (⑦−①) | AI4: Telat laycan (④−laycan akhir) | AJ4: Kelengkapan tanggal | AK4: Cek
A5: =IF(B5="","",ROW()-4) -> 1 | B5: KCL | C5: KCL 1st | D5: 2022 | E5: Kanada | F5: Vancouver,Canada | G5: PKG Port , Gresik | H5: K+S Minerals and Agriculture GmbH | I5: MV Federal Illinois | K5: 27500 | U5: Selesai | Y5: 28 | Z5: LT History 2022–2024 | AA5: =IF(AND(ISNUMBER(L5),ISNUMBER(M5)),M5-L5,"") | AB5: =IF(AND(ISNUMBER(M5),ISNUMBER(P5)),P5-M5,"") | AC5: =IF(AND(ISNUMBER(L5),ISNUMBER(P5)),P5-L5,"") | AD5: =IF(AND(ISNUMBER(P5),ISNUMBER(Q5)),Q5-P5,"") | AE5: =IF(AND(ISNUMBER(Q5),ISNUMBER(R5)),R5-Q5,IF(ISNUMBER(Y5),Y5,"")) -> 28 | AF5: =IF(AND(ISNUMBER(R5),ISNUMBER(S5)),S5-R5,"") | AG5: =IF(AND(ISNUMBER(S5),ISNUMBER(T5)),T5-S5,"") | AH5: =IF(AND(ISNUMBER(L5),ISNUMBER(T5)),T5-L5,"") | AI5: =IF(AND(ISNUMBER(O5),ISNUMBER(Q5)),Q5-O5,"") | AJ5: =IF(B5="","",COUNT(L5:M5,P5:T5)&"/7") -> 0/7 | AK5: =IF(B5="","",IF(OR(AND(ISNUMBER(L5),ISNUMBER(M5),M5<L5),AND(ISNUMBER(M5),ISNUMBER(P5),P5<M5),AND(ISNUMBER(P5),ISNUMBER(Q5),Q5<P5),AND(ISNUMBER(Q5),ISNUMBER(R5),R5<Q5),AND(ISNUMBER(R5),ISNUMBER(S5),S5<R5),AND(ISNUMBER(S5),ISNUMBER(T5),T5<S5),AND(ISNUMBER(N5),ISNUMBER(O5),O5<N5)),"Urutan tanggal salah",IF(AND(ISNUMBER(Q5),ISNUMBER(R5),ISNUMBER(Y5),ABS(R5-Q5-Y5)>2),"S tanggal ≠ Sailing tercatat",IF(AND(ISNUMBER(Q5),ISNUMBER(O5),ABS(Q5-O5)>60),"Cek tahun laycan",IF(AND(ISNUMBER(Q5),ISNUMBER(N5),Q5<N5),"Berangkat sebelum laycan",IF(NOT(ISNUMBER(AE5)),"S belum ada","OK")))))) -> OK
A6: =IF(B6="","",ROW()-4) -> 2 | B6: KCL | C6: KCL 2nd | D6: 2022 | E6: Kanada | F6: Vancouver,Canada | G6: PKG Port , Gresik | H6: K+S Minerals and Agriculture GmbH | I6: MV Star Gaia | K6: 26510 | N6: 44674 | O6: 44674 | Q6: 44675 | R6: 44703 | U6: Selesai | Y6: 28 | Z6: LT History 2022–2024 | AA6: =IF(AND(ISNUMBER(L6),ISNUMBER(M6)),M6-L6,"") | AB6: =IF(AND(ISNUMBER(M6),ISNUMBER(P6)),P6-M6,"") | AC6: =IF(AND(ISNUMBER(L6),ISNUMBER(P6)),P6-L6,"") | AD6: =IF(AND(ISNUMBER(P6),ISNUMBER(Q6)),Q6-P6,"") | AE6: =IF(AND(ISNUMBER(Q6),ISNUMBER(R6)),R6-Q6,IF(ISNUMBER(Y6),Y6,"")) -> 28 | AF6: =IF(AND(ISNUMBER(R6),ISNUMBER(S6)),S6-R6,"") | AG6: =IF(AND(ISNUMBER(S6),ISNUMBER(T6)),T6-S6,"") | AH6: =IF(AND(ISNUMBER(L6),ISNUMBER(T6)),T6-L6,"") | AI6: =IF(AND(ISNUMBER(O6),ISNUMBER(Q6)),Q6-O6,"") -> 1 | AJ6: =IF(B6="","",COUNT(L6:M6,P6:T6)&"/7") -> 2/7 | AK6: =IF(B6="","",IF(OR(AND(ISNUMBER(L6),ISNUMBER(M6),M6<L6),AND(ISNUMBER(M6),ISNUMBER(P6),P6<M6),AND(ISNUMBER(P6),ISNUMBER(Q6),Q6<P6),AND(ISNUMBER(Q6),ISNUMBER(R6),R6<Q6),AND(ISNUMBER(R6),ISNUMBER(S6),S6<R6),AND(ISNUMBER(S6),ISNUMBER(T6),T6<S6),AND(ISNUMBER(N6),ISNUMBER(O6),O6<N6)),"Urutan tanggal salah",IF(AND(ISNUMBER(Q6),ISNUMBER(R6),ISNUMBER(Y6),ABS(R6-Q6-Y6)>2),"S tanggal ≠ Sailing tercatat",IF(AND(ISNUMBER(Q6),ISNUMBER(O6),ABS(Q6-O6)>60),"Cek tahun laycan",IF(AND(ISNUMBER(Q6),ISNUMBER(N6),Q6<N6),"Berangkat sebelum laycan",IF(NOT(ISNUMBER(AE6)),"S belum ada","OK")))))) -> OK
A7: =IF(B7="","",ROW()-4) -> 3 | B7: KCL | C7: KCL 1st | D7: 2022 | E7: Kanada | F7: Vancouver,Canada | G7: PKG Port , Gresik | H7: Aastar/Canpotex | I7: MV Theresa Grace | K7: 27500 | U7: Selesai | Y7: 28 | Z7: LT History 2022–2024 | AA7: =IF(AND(ISNUMBER(L7),ISNUMBER(M7)),M7-L7,"") | AB7: =IF(AND(ISNUMBER(M7),ISNUMBER(P7)),P7-M7,"") | AC7: =IF(AND(ISNUMBER(L7),ISNUMBER(P7)),P7-L7,"") | AD7: =IF(AND(ISNUMBER(P7),ISNUMBER(Q7)),Q7-P7,"") | AE7: =IF(AND(ISNUMBER(Q7),ISNUMBER(R7)),R7-Q7,IF(ISNUMBER(Y7),Y7,"")) -> 28 | AF7: =IF(AND(ISNUMBER(R7),ISNUMBER(S7)),S7-R7,"") | AG7: =IF(AND(ISNUMBER(S7),ISNUMBER(T7)),T7-S7,"") | AH7: =IF(AND(ISNUMBER(L7),ISNUMBER(T7)),T7-L7,"") | AI7: =IF(AND(ISNUMBER(O7),ISNUMBER(Q7)),Q7-O7,"") | AJ7: =IF(B7="","",COUNT(L7:M7,P7:T7)&"/7") -> 0/7 | AK7: =IF(B7="","",IF(OR(AND(ISNUMBER(L7),ISNUMBER(M7),M7<L7),AND(ISNUMBER(M7),ISNUMBER(P7),P7<M7),AND(ISNUMBER(P7),ISNUMBER(Q7),Q7<P7),AND(ISNUMBER(Q7),ISNUMBER(R7),R7<Q7),AND(ISNUMBER(R7),ISNUMBER(S7),S7<R7),AND(ISNUMBER(S7),ISNUMBER(T7),T7<S7),AND(ISNUMBER(N7),ISNUMBER(O7),O7<N7)),"Urutan tanggal salah",IF(AND(ISNUMBER(Q7),ISNUMBER(R7),ISNUMBER(Y7),ABS(R7-Q7-Y7)>2),"S tanggal ≠ Sailing tercatat",IF(AND(ISNUMBER(Q7),ISNUMBER(O7),ABS(Q7-O7)>60),"Cek tahun laycan",IF(AND(ISNUMBER(Q7),ISNUMBER(N7),Q7<N7),"Berangkat sebelum laycan",IF(NOT(ISNUMBER(AE7)),"S belum ada","OK")))))) -> OK
A8: =IF(B8="","",ROW()-4) -> 4 | B8: KCL | C8: KCL 2nd | D8: 2022 | E8: Kanada | F8: Vancouver,Canada | G8: PKG Port , Gresik | H8: Aastar/Canpotex | I8: MV Port Vera Cruz | K8: 27500 | U8: Selesai | Y8: 28 | Z8: LT History 2022–2024 | AA8: =IF(AND(ISNUMBER(L8),ISNUMBER(M8)),M8-L8,"") | AB8: =IF(AND(ISNUMBER(M8),ISNUMBER(P8)),P8-M8,"") | AC8: =IF(AND(ISNUMBER(L8),ISNUMBER(P8)),P8-L8,"") | AD8: =IF(AND(ISNUMBER(P8),ISNUMBER(Q8)),Q8-P8,"") | AE8: =IF(AND(ISNUMBER(Q8),ISNUMBER(R8)),R8-Q8,IF(ISNUMBER(Y8),Y8,"")) -> 28 | AF8: =IF(AND(ISNUMBER(R8),ISNUMBER(S8)),S8-R8,"") | AG8: =IF(AND(ISNUMBER(S8),ISNUMBER(T8)),T8-S8,"") | AH8: =IF(AND(ISNUMBER(L8),ISNUMBER(T8)),T8-L8,"") | AI8: =IF(AND(ISNUMBER(O8),ISNUMBER(Q8)),Q8-O8,"") | AJ8: =IF(B8="","",COUNT(L8:M8,P8:T8)&"/7") -> 0/7 | AK8: =IF(B8="","",IF(OR(AND(ISNUMBER(L8),ISNUMBER(M8),M8<L8),AND(ISNUMBER(M8),ISNUMBER(P8),P8<M8),AND(ISNUMBER(P8),ISNUMBER(Q8),Q8<P8),AND(ISNUMBER(Q8),ISNUMBER(R8),R8<Q8),AND(ISNUMBER(R8),ISNUMBER(S8),S8<R8),AND(ISNUMBER(S8),ISNUMBER(T8),T8<S8),AND(ISNUMBER(N8),ISNUMBER(O8),O8<N8)),"Urutan tanggal salah",IF(AND(ISNUMBER(Q8),ISNUMBER(R8),ISNUMBER(Y8),ABS(R8-Q8-Y8)>2),"S tanggal ≠ Sailing tercatat",IF(AND(ISNUMBER(Q8),ISNUMBER(O8),ABS(Q8-O8)>60),"Cek tahun laycan",IF(AND(ISNUMBER(Q8),ISNUMBER(N8),Q8<N8),"Berangkat sebelum laycan",IF(NOT(ISNUMBER(AE8)),"S belum ada","OK")))))) -> OK
A9: =IF(B9="","",ROW()-4) -> 5 | B9: KCL | C9: KCL 3rd | D9: 2022 | E9: Kanada | F9: Vancouver,Canada | G9: PKG Port , Gresik | H9: Aastar/Canpotex | I9: MV HSL Mexico | K9: 27146 | U9: Selesai | Y9: 28 | Z9: LT History 2022–2024 | AA9: =IF(AND(ISNUMBER(L9),ISNUMBER(M9)),M9-L9,"") | AB9: =IF(AND(ISNUMBER(M9),ISNUMBER(P9)),P9-M9,"") | AC9: =IF(AND(ISNUMBER(L9),ISNUMBER(P9)),P9-L9,"") | AD9: =IF(AND(ISNUMBER(P9),ISNUMBER(Q9)),Q9-P9,"") | AE9: =IF(AND(ISNUMBER(Q9),ISNUMBER(R9)),R9-Q9,IF(ISNUMBER(Y9),Y9,"")) -> 28 | AF9: =IF(AND(ISNUMBER(R9),ISNUMBER(S9)),S9-R9,"") | AG9: =IF(AND(ISNUMBER(S9),ISNUMBER(T9)),T9-S9,"") | AH9: =IF(AND(ISNUMBER(L9),ISNUMBER(T9)),T9-L9,"") | AI9: =IF(AND(ISNUMBER(O9),ISNUMBER(Q9)),Q9-O9,"") | AJ9: =IF(B9="","",COUNT(L9:M9,P9:T9)&"/7") -> 0/7 | AK9: =IF(B9="","",IF(OR(AND(ISNUMBER(L9),ISNUMBER(M9),M9<L9),AND(ISNUMBER(M9),ISNUMBER(P9),P9<M9),AND(ISNUMBER(P9),ISNUMBER(Q9),Q9<P9),AND(ISNUMBER(Q9),ISNUMBER(R9),R9<Q9),AND(ISNUMBER(R9),ISNUMBER(S9),S9<R9),AND(ISNUMBER(S9),ISNUMBER(T9),T9<S9),AND(ISNUMBER(N9),ISNUMBER(O9),O9<N9)),"Urutan tanggal salah",IF(AND(ISNUMBER(Q9),ISNUMBER(R9),ISNUMBER(Y9),ABS(R9-Q9-Y9)>2),"S tanggal ≠ Sailing tercatat",IF(AND(ISNUMBER(Q9),ISNUMBER(O9),ABS(Q9-O9)>60),"Cek tahun laycan",IF(AND(ISNUMBER(Q9),ISNUMBER(N9),Q9<N9),"Berangkat sebelum laycan",IF(NOT(ISNUMBER(AE9)),"S belum ada","OK")))))) -> OK
A10: =IF(B10="","",ROW()-4) -> 6 | B10: KCL | C10: KCL | D10: 2022 | E10: Russia | F10: Novorossiysk, Russia | G10: PKG Port , Gresik | H10: Eurochem Trading Middle East DMCC | I10: MV GM Legend | K10: 27533 | U10: Selesai | Y10: 28 | Z10: LT History 2022–2024 | AA10: =IF(AND(ISNUMBER(L10),ISNUMBER(M10)),M10-L10,"") | AB10: =IF(AND(ISNUMBER(M10),ISNUMBER(P10)),P10-M10,"") | AC10: =IF(AND(ISNUMBER(L10),ISNUMBER(P10)),P10-L10,"") | AD10: =IF(AND(ISNUMBER(P10),ISNUMBER(Q10)),Q10-P10,"") | AE10: =IF(AND(ISNUMBER(Q10),ISNUMBER(R10)),R10-Q10,IF(ISNUMBER(Y10),Y10,"")) -> 28 | AF10: =IF(AND(ISNUMBER(R10),ISNUMBER(S10)),S10-R10,"") | AG10: =IF(AND(ISNUMBER(S10),ISNUMBER(T10)),T10-S10,"") | AH10: =IF(AND(ISNUMBER(L10),ISNUMBER(T10)),T10-L10,"") | AI10: =IF(AND(ISNUMBER(O10),ISNUMBER(Q10)),Q10-O10,"") | AJ10: =IF(B10="","",COUNT(L10:M10,P10:T10)&"/7") -> 0/7 | AK10: =IF(B10="","",IF(OR(AND(ISNUMBER(L10),ISNUMBER(M10),M10<L10),AND(ISNUMBER(M10),ISNUMBER(P10),P10<M10),AND(ISNUMBER(P10),ISNUMBER(Q10),Q10<P10),AND(ISNUMBER(Q10),ISNUMBER(R10),R10<Q10),AND(ISNUMBER(R10),ISNUMBER(S10),S10<R10),AND(ISNUMBER(S10),ISNUMBER(T10),T10<S10),AND(ISNUMBER(N10),ISNUMBER(O10),O10<N10)),"Urutan tanggal salah",IF(AND(ISNUMBER(Q10),ISNUMBER(R10),ISNUMBER(Y10),ABS(R10-Q10-Y10)>2),"S tanggal ≠ Sailing tercatat",IF(AND(ISNUMBER(Q10),ISNUMBER(O10),ABS(Q10-O10)>60),"Cek tahun laycan",IF(AND(ISNUMBER(Q10),ISNUMBER(N10),Q10<N10),"Berangkat sebelum laycan",IF(NOT(ISNUMBER(AE10)),"S belum ada","OK")))))) -> OK
A11: =IF(B11="","",ROW()-4) -> 7 | B11: KCL | C11: KCL 1st | D11: 2022 | E11: Jordan | F11: Aqaba, Jordan | G11: PKG Port , Gresik | H11: APC | I11: MV Golden Bright | K11: 23500 | U11: Selesai | Y11: 28 | Z11: LT History 2022–2024 | AA11: =IF(AND(ISNUMBER(L11),ISNUMBER(M11)),M11-L11,"") | AB11: =IF(AND(ISNUMBER(M11),ISNUMBER(P11)),P11-M11,"") | AC11: =IF(AND(ISNUMBER(L11),ISNUMBER(P11)),P11-L11,"") | AD11: =IF(AND(ISNUMBER(P11),ISNUMBER(Q11)),Q11-P11,"") | AE11: =IF(AND(ISNUMBER(Q11),ISNUMBER(R11)),R11-Q11,IF(ISNUMBER(Y11),Y11,"")) -> 28 | AF11: =IF(AND(ISNUMBER(R11),ISNUMBER(S11)),S11-R11,"") | AG11: =IF(AND(ISNUMBER(S11),ISNUMBER(T11)),T11-S11,"") | AH11: =IF(AND(ISNUMBER(L11),ISNUMBER(T11)),T11-L11,"") | AI11: =IF(AND(ISNUMBER(O11),ISNUMBER(Q11)),Q11-O11,"") | AJ11: =IF(B11="","",COUNT(L11:M11,P11:T11)&"/7") -> 0/7 | AK11: =IF(B11="","",IF(OR(AND(ISNUMBER(L11),ISNUMBER(M11),M11<L11),AND(ISNUMBER(M11),ISNUMBER(P11),P11<M11),AND(ISNUMBER(P11),ISNUMBER(Q11),Q11<P11),AND(ISNUMBER(Q11),ISNUMBER(R11),R11<Q11),AND(ISNUMBER(R11),ISNUMBER(S11),S11<R11),AND(ISNUMBER(S11),ISNUMBER(T11),T11<S11),AND(ISNUMBER(N11),ISNUMBER(O11),O11<N11)),"Urutan tanggal salah",IF(AND(ISNUMBER(Q11),ISNUMBER(R11),ISNUMBER(Y11),ABS(R11-Q11-Y11)>2),"S tanggal ≠ Sailing tercatat",IF(AND(ISNUMBER(Q11),ISNUMBER(O11),ABS(Q11-O11)>60),"Cek tahun laycan",IF(AND(ISNUMBER(Q11),ISNUMBER(N11),Q11<N11),"Berangkat sebelum laycan",IF(NOT(ISNUMBER(AE11)),"S belum ada","OK")))))) -> OK
A12: =IF(B12="","",ROW()-4) -> 8 | B12: KCL | C12: KCL | D12: 2022 | E12: Laos | F12: Vung Ang,Vietnam | G12: PKG Port , Gresik | H12: Lao Kaiyuan | I12: MV Hong Linh 1 | K12: 11000 | N12: 44723 | O12: 44723 | Q12: 44724 | R12: 44731 | U12: Selesai | Y12: 7 | Z12: LT History 2022–2024 | AA12: =IF(AND(ISNUMBER(L12),ISNUMBER(M12)),M12-L12,"") | AB12: =IF(AND(ISNUMBER(M12),ISNUMBER(P12)),P12-M12,"") | AC12: =IF(AND(ISNUMBER(L12),ISNUMBER(P12)),P12-L12,"") | AD12: =IF(AND(ISNUMBER(P12),ISNUMBER(Q12)),Q12-P12,"") | AE12: =IF(AND(ISNUMBER(Q12),ISNUMBER(R12)),R12-Q12,IF(ISNUMBER(Y12),Y12,"")) -> 7 | AF12: =IF(AND(ISNUMBER(R12),ISNUMBER(S12)),S12-R12,"") | AG12: =IF(AND(ISNUMBER(S12),ISNUMBER(T12)),T12-S12,"") | AH12: =IF(AND(ISNUMBER(L12),ISNUMBER(T12)),T12-L12,"") | AI12: =IF(AND(ISNUMBER(O12),ISNUMBER(Q12)),Q12-O12,"") -> 1 | AJ12: =IF(B12="","",COUNT(L12:M12,P12:T12)&"/7") -> 2/7 | AK12: =IF(B12="","",IF(OR(AND(ISNUMBER(L12),ISNUMBER(M12),M12<L12),AND(ISNUMBER(M12),ISNUMBER(P12),P12<M12),AND(ISNUMBER(P12),ISNUMBER(Q12),Q12<P12),AND(ISNUMBER(Q12),ISNUMBER(R12),R12<Q12),AND(ISNUMBER(R12),ISNUMBER(S12),S12<R12),AND(ISNUMBER(S12),ISNUMBER(T12),T12<S12),AND(ISNUMBER(N12),ISNUMBER(O12),O12<N12)),"Urutan tanggal salah",IF(AND(ISNUMBER(Q12),ISNUMBER(R12),ISNUMBER(Y12),ABS(R12-Q12-Y12)>2),"S tanggal ≠ Sailing tercatat",IF(AND(ISNUMBER(Q12),ISNUMBER(O12),ABS(Q12-O12)>60),"Cek tahun laycan",IF(AND(ISNUMBER(Q12),ISNUMBER(N12),Q12<N12),"Berangkat sebelum laycan",IF(NOT(ISNUMBER(AE12)),"S belum ada","OK")))))) -> OK
A13: =IF(B13="","",ROW()-4) -> 9 | B13: KCL | C13: KCL 1st | D13: 2022 | E13: Jordan | F13: Aqaba, Jordan | G13: PKG Port , Gresik | H13: APC | I13: MV Andean | K13: 25000 | N13: 44738 | O13: 44738 | Q13: 44743 | R13: 44761 | U13: Selesai | Y13: 18 | Z13: LT History 2022–2024 | AA13: =IF(AND(ISNUMBER(L13),ISNUMBER(M13)),M13-L13,"") | AB13: =IF(AND(ISNUMBER(M13),ISNUMBER(P13)),P13-M13,"") | AC13: =IF(AND(ISNUMBER(L13),ISNUMBER(P13)),P13-L13,"") | AD13: =IF(AND(ISNUMBER(P13),ISNUMBER(Q13)),Q13-P13,"") | AE13: =IF(AND(ISNUMBER(Q13),ISNUMBER(R13)),R13-Q13,IF(ISNUMBER(Y13),Y13,"")) -> 18 | AF13: =IF(AND(ISNUMBER(R13),ISNUMBER(S13)),S13-R13,"") | AG13: =IF(AND(ISNUMBER(S13),ISNUMBER(T13)),T13-S13,"") | AH13: =IF(AND(ISNUMBER(L13),ISNUMBER(T13)),T13-L13,"") | AI13: =IF(AND(ISNUMBER(O13),ISNUMBER(Q13)),Q13-O13,"") -> 5 | AJ13: =IF(B13="","",COUNT(L13:M13,P13:T13)&"/7") -> 2/7 | AK13: =IF(B13="","",IF(OR(AND(ISNUMBER(L13),ISNUMBER(M13),M13<L13),AND(ISNUMBER(M13),ISNUMBER(P13),P13<M13),AND(ISNUMBER(P13),ISNUMBER(Q13),Q13<P13),AND(ISNUMBER(Q13),ISNUMBER(R13),R13<Q13),AND(ISNUMBER(R13),ISNUMBER(S13),S13<R13),AND(ISNUMBER(S13),ISNUMBER(T13),T13<S13),AND(ISNUMBER(N13),ISNUMBER(O13),O13<N13)),"Urutan tanggal salah",IF(AND(ISNUMBER(Q13),ISNUMBER(R13),ISNUMBER(Y13),ABS(R13-Q13-Y13)>2),"S tanggal ≠ Sailing tercatat",IF(AND(ISNUMBER(Q13),ISNUMBER(O13),ABS(Q13-O13)>60),"Cek tahun laycan",IF(AND(ISNUMBER(Q13),ISNUMBER(N13),Q13<N13),"Berangkat sebelum laycan",IF(NOT(ISNUMBER(AE13)),"S belum ada","OK")))))) -> OK
A14: =IF(B14="","",ROW()-4) -> 10 | B14: KCL | C14: KCL 2nd | D14: 2022 | E14: Jordan | F14: Aqaba, Jordan | G14: PKG Port , Gresik | H14: APC/ Clementcorp | I14: MV. TEAM FOCUS | K14: 25000 | N14: 44828 | O14: 44828 | Q14: 44831 | R14: 44853 | U14: Selesai | Y14: 22 | Z14: LT History 2022–2024 | AA14: =IF(AND(ISNUMBER(L14),ISNUMBER(M14)),M14-L14,"") | AB14: =IF(AND(ISNUMBER(M14),ISNUMBER(P14)),P14-M14,"") | AC14: =IF(AND(ISNUMBER(L14),ISNUMBER(P14)),P14-L14,"") | AD14: =IF(AND(ISNUMBER(P14),ISNUMBER(Q14)),Q14-P14,"") | AE14: =IF(AND(ISNUMBER(Q14),ISNUMBER(R14)),R14-Q14,IF(ISNUMBER(Y14),Y14,"")) -> 22 | AF14: =IF(AND(ISNUMBER(R14),ISNUMBER(S14)),S14-R14,"") | AG14: =IF(AND(ISNUMBER(S14),ISNUMBER(T14)),T14-S14,"") | AH14: =IF(AND(ISNUMBER(L14),ISNUMBER(T14)),T14-L14,"") | AI14: =IF(AND(ISNUMBER(O14),ISNUMBER(Q14)),Q14-O14,"") -> 3 | AJ14: =IF(B14="","",COUNT(L14:M14,P14:T14)&"/7") -> 2/7 | AK14: =IF(B14="","",IF(OR(AND(ISNUMBER(L14),ISNUMBER(M14),M14<L14),AND(ISNUMBER(M14),ISNUMBER(P14),P14<M14),AND(ISNUMBER(P14),ISNUMBER(Q14),Q14<P14),AND(ISNUMBER(Q14),ISNUMBER(R14),R14<Q14),AND(ISNUMBER(R14),ISNUMBER(S14),S14<R14),AND(ISNUMBER(S14),ISNUMBER(T14),T14<S14),AND(ISNUMBER(N14),ISNUMBER(O14),O14<N14)),"Urutan tanggal salah",IF(AND(ISNUMBER(Q14),ISNUMBER(R14),ISNUMBER(Y14),ABS(R14-Q14-Y14)>2),"S tanggal ≠ Sailing tercatat",IF(AND(ISNUMBER(Q14),ISNUMBER(O14),ABS(Q14-O14)>60),"Cek tahun laycan",IF(AND(ISNUMBER(Q14),ISNUMBER(N14),Q14<N14),"Berangkat sebelum laycan",IF(NOT(ISNUMBER(AE14)),"S belum ada","OK")))))) -> OK
A15: =IF(B15="","",ROW()-4) -> 11 | B15: KCL | C15: KCL | D15: 2022 | E15: Laos | F15: Vung Ang,Vietnam | G15: PKG Port , Gresik | H15: Sino Agri | I15: MV Lucky Star | K15: 21000 | N15: 44754 | O15: 44754 | Q15: 44754 | R15: 44761 | U15: Selesai | Y15: 7 | Z15: LT History 2022–2024 | AA15: =IF(AND(ISNUMBER(L15),ISNUMBER(M15)),M15-L15,"") | AB15: =IF(AND(ISNUMBER(M15),ISNUMBER(P15)),P15-M15,"") | AC15: =IF(AND(ISNUMBER(L15),ISNUMBER(P15)),P15-L15,"") | AD15: =IF(AND(ISNUMBER(P15),ISNUMBER(Q15)),Q15-P15,"") | AE15: =IF(AND(ISNUMBER(Q15),ISNUMBER(R15)),R15-Q15,IF(ISNUMBER(Y15),Y15,"")) -> 7 | AF15: =IF(AND(ISNUMBER(R15),ISNUMBER(S15)),S15-R15,"") | AG15: =IF(AND(ISNUMBER(S15),ISNUMBER(T15)),T15-S15,"") | AH15: =IF(AND(ISNUMBER(L15),ISNUMBER(T15)),T15-L15,"") | AI15: =IF(AND(ISNUMBER(O15),ISNUMBER(Q15)),Q15-O15,"") -> 0 | AJ15: =IF(B15="","",COUNT(L15:M15,P15:T15)&"/7") -> 2/7 | AK15: =IF(B15="","",IF(OR(AND(ISNUMBER(L15),ISNUMBER(M15),M15<L15),AND(ISNUMBER(M15),ISNUMBER(P15),P15<M15),AND(ISNUMBER(P15),ISNUMBER(Q15),Q15<P15),AND(ISNUMBER(Q15),ISNUMBER(R15),R15<Q15),AND(ISNUMBER(R15),ISNUMBER(S15),S15<R15),AND(ISNUMBER(S15),ISNUMBER(T15),T15<S15),AND(ISNUMBER(N15),ISNUMBER(O15),O15<N15)),"Urutan tanggal salah",IF(AND(ISNUMBER(Q15),ISNUMBER(R15),ISNUMBER(Y15),ABS(R15-Q15-Y15)>2),"S tanggal ≠ Sailing tercatat",IF(AND(ISNUMBER(Q15),ISNUMBER(O15),ABS(Q15-O15)>60),"Cek tahun laycan",IF(AND(ISNUMBER(Q15),ISNUMBER(N15),Q15<N15),"Berangkat sebelum laycan",IF(NOT(ISNUMBER(AE15)),"S belum ada","OK")))))) -> OK
A16: =IF(B16="","",ROW()-4) -> 12 | B16: KCL | C16: KCL 1st | D16: 2022 | E16: Russia | F16: Novorossiysk, Russia | G16: PKG Port , Gresik | H16: Eurochem Trading Middle East DMCC | I16: MV ABK Tiger | K16: 27365 | N16: 44707 | O16: 44707 | Q16: 44713 | R16: 44744 | U16: Selesai | X16: 26-Mei-2022 | Y16: 31 | Z16: LT History 2022–2024 | AA16: =IF(AND(ISNUMBER(L16),ISNUMBER(M16)),M16-L16,"") | AB16: =IF(AND(ISNUMBER(M16),ISNUMBER(P16)),P16-M16,"") | AC16: =IF(AND(ISNUMBER(L16),ISNUMBER(P16)),P16-L16,"") | AD16: =IF(AND(ISNUMBER(P16),ISNUMBER(Q16)),Q16-P16,"") | AE16: =IF(AND(ISNUMBER(Q16),ISNUMBER(R16)),R16-Q16,IF(ISNUMBER(Y16),Y16,"")) -> 31 | AF16: =IF(AND(ISNUMBER(R16),ISNUMBER(S16)),S16-R16,"") | AG16: =IF(AND(ISNUMBER(S16),ISNUMBER(T16)),T16-S16,"") | AH16: =IF(AND(ISNUMBER(L16),ISNUMBER(T16)),T16-L16,"") | AI16: =IF(AND(ISNUMBER(O16),ISNUMBER(Q16)),Q16-O16,"") -> 6 | AJ16: =IF(B16="","",COUNT(L16:M16,P16:T16)&"/7") -> 2/7 | AK16: =IF(B16="","",IF(OR(AND(ISNUMBER(L16),ISNUMBER(M16),M16<L16),AND(ISNUMBER(M16),ISNUMBER(P16),P16<M16),AND(ISNUMBER(P16),ISNUMBER(Q16),Q16<P16),AND(ISNUMBER(Q16),ISNUMBER(R16),R16<Q16),AND(ISNUMBER(R16),ISNUMBER(S16),S16<R16),AND(ISNUMBER(S16),ISNUMBER(T16),T16<S16),AND(ISNUMBER(N16),ISNUMBER(O16),O16<N16)),"Urutan tanggal salah",IF(AND(ISNUMBER(Q16),ISNUMBER(R16),ISNUMBER(Y16),ABS(R16-Q16-Y16)>2),"S tanggal ≠ Sailing tercatat",IF(AND(ISNUMBER(Q16),ISNUMBER(O16),ABS(Q16-O16)>60),"Cek tahun laycan",IF(AND(ISNUMBER(Q16),ISNUMBER(N16),Q16<N16),"Berangkat sebelum laycan",IF(NOT(ISNUMBER(AE16)),"S belum ada","OK")))))) -> OK
A17: =IF(B17="","",ROW()-4) -> 13 | B17: KCL | C17: KCL 2nd | D17: 2022 | E17: Russia | F17: Novorossiysk, Russia | G17: PKG Port , Gresik | H17: Eurochem Trading Middle East DMCC | I17: MV Ludogorets | K17: 13500 | N17: 44724 | O17: 44724 | Q17: 44725 | R17: 44757 | U17: Selesai | Y17: 32 | Z17: LT History 2022–2024 | AA17: =IF(AND(ISNUMBER(L17),ISNUMBER(M17)),M17-L17,"") | AB17: =IF(AND(ISNUMBER(M17),ISNUMBER(P17)),P17-M17,"") | AC17: =IF(AND(ISNUMBER(L17),ISNUMBER(P17)),P17-L17,"") | AD17: =IF(AND(ISNUMBER(P17),ISNUMBER(Q17)),Q17-P17,"") | AE17: =IF(AND(ISNUMBER(Q17),ISNUMBER(R17)),R17-Q17,IF(ISNUMBER(Y17),Y17,"")) -> 32 | AF17: =IF(AND(ISNUMBER(R17),ISNUMBER(S17)),S17-R17,"") | AG17: =IF(AND(ISNUMBER(S17),ISNUMBER(T17)),T17-S17,"") | AH17: =IF(AND(ISNUMBER(L17),ISNUMBER(T17)),T17-L17,"") | AI17: =IF(AND(ISNUMBER(O17),ISNUMBER(Q17)),Q17-O17,"") -> 1 | AJ17: =IF(B17="","",COUNT(L17:M17,P17:T17)&"/7") -> 2/7 | AK17: =IF(B17="","",IF(OR(AND(ISNUMBER(L17),ISNUMBER(M17),M17<L17),AND(ISNUMBER(M17),ISNUMBER(P17),P17<M17),AND(ISNUMBER(P17),ISNUMBER(Q17),Q17<P17),AND(ISNUMBER(Q17),ISNUMBER(R17),R17<Q17),AND(ISNUMBER(R17),ISNUMBER(S17),S17<R17),AND(ISNUMBER(S17),ISNUMBER(T17),T17<S17),AND(ISNUMBER(N17),ISNUMBER(O17),O17<N17)),"Urutan tanggal salah",IF(AND(ISNUMBER(Q17),ISNUMBER(R17),ISNUMBER(Y17),ABS(R17-Q17-Y17)>2),"S tanggal ≠ Sailing tercatat",IF(AND(ISNUMBER(Q17),ISNUMBER(O17),ABS(Q17-O17)>60),"Cek tahun laycan",IF(AND(ISNUMBER(Q17),ISNUMBER(N17),Q17<N17),"Berangkat sebelum laycan",IF(NOT(ISNUMBER(AE17)),"S belum ada","OK")))))) -> OK
A18: =IF(B18="","",ROW()-4) -> 14 | B18: KCL | C18: KCL 2nd | D18: 2022 | E18: Russia | F18: Ust Luga, Russia | G18: PKG Port , Gresik | H18: Eurochem Trading Middle East DMCC | I18: MV Orcun C | K18: 14000 | N18: 44724 | O18: 44724 | Q18: 44725 | R18: 44762 | U18: Selesai | Y18: 37 | Z18: LT History 2022–2024 | AA18: =IF(AND(ISNUMBER(L18),ISNUMBER(M18)),M18-L18,"") | AB18: =IF(AND(ISNUMBER(M18),ISNUMBER(P18)),P18-M18,"") | AC18: =IF(AND(ISNUMBER(L18),ISNUMBER(P18)),P18-L18,"") | AD18: =IF(AND(ISNUMBER(P18),ISNUMBER(Q18)),Q18-P18,"") | AE18: =IF(AND(ISNUMBER(Q18),ISNUMBER(R18)),R18-Q18,IF(ISNUMBER(Y18),Y18,"")) -> 37 | AF18: =IF(AND(ISNUMBER(R18),ISNUMBER(S18)),S18-R18,"") | AG18: =IF(AND(ISNUMBER(S18),ISNUMBER(T18)),T18-S18,"") | AH18: =IF(AND(ISNUMBER(L18),ISNUMBER(T18)),T18-L18,"") | AI18: =IF(AND(ISNUMBER(O18),ISNUMBER(Q18)),Q18-O18,"") -> 1 | AJ18: =IF(B18="","",COUNT(L18:M18,P18:T18)&"/7") -> 2/7 | AK18: =IF(B18="","",IF(OR(AND(ISNUMBER(L18),ISNUMBER(M18),M18<L18),AND(ISNUMBER(M18),ISNUMBER(P18),P18<M18),AND(ISNUMBER(P18),ISNUMBER(Q18),Q18<P18),AND(ISNUMBER(Q18),ISNUMBER(R18),R18<Q18),AND(ISNUMBER(R18),ISNUMBER(S18),S18<R18),AND(ISNUMBER(S18),ISNUMBER(T18),T18<S18),AND(ISNUMBER(N18),ISNUMBER(O18),O18<N18)),"Urutan tanggal salah",IF(AND(ISNUMBER(Q18),ISNUMBER(R18),ISNUMBER(Y18),ABS(R18-Q18-Y18)>2),"S tanggal ≠ Sailing tercatat",IF(AND(ISNUMBER(Q18),ISNUMBER(O18),ABS(Q18-O18)>60),"Cek tahun laycan",IF(AND(ISNUMBER(Q18),ISNUMBER(N18),Q18<N18),"Berangkat sebelum laycan",IF(NOT(ISNUMBER(AE18)),"S belum ada","OK")))))) -> OK
A19: =IF(B19="","",ROW()-4) -> 15 | B19: KCL | C19: KCL 1st | D19: 2022 | E19: Kanada | F19: Vancouver, Canada | G19: PKG Port , Gresik | H19: Aastar/Canpotex | I19: MV PMS Seagull | K19: 27500 | N19: 44765 | O19: 44765 | Q19: 44766 | R19: 44794 | U19: Selesai | Y19: 28 | Z19: LT History 2022–2024 | AA19: =IF(AND(ISNUMBER(L19),ISNUMBER(M19)),M19-L19,"") | AB19: =IF(AND(ISNUMBER(M19),ISNUMBER(P19)),P19-M19,"") | AC19: =IF(AND(ISNUMBER(L19),ISNUMBER(P19)),P19-L19,"") | AD19: =IF(AND(ISNUMBER(P19),ISNUMBER(Q19)),Q19-P19,"") | AE19: =IF(AND(ISNUMBER(Q19),ISNUMBER(R19)),R19-Q19,IF(ISNUMBER(Y19),Y19,"")) -> 28 | AF19: =IF(AND(ISNUMBER(R19),ISNUMBER(S19)),S19-R19,"") | AG19: =IF(AND(ISNUMBER(S19),ISNUMBER(T19)),T19-S19,"") | AH19: =IF(AND(ISNUMBER(L19),ISNUMBER(T19)),T19-L19,"") | AI19: =IF(AND(ISNUMBER(O19),ISNUMBER(Q19)),Q19-O19,"") -> 1 | AJ19: =IF(B19="","",COUNT(L19:M19,P19:T19)&"/7") -> 2/7 | AK19: =IF(B19="","",IF(OR(AND(ISNUMBER(L19),ISNUMBER(M19),M19<L19),AND(ISNUMBER(M19),ISNUMBER(P19),P19<M19),AND(ISNUMBER(P19),ISNUMBER(Q19),Q19<P19),AND(ISNUMBER(Q19),ISNUMBER(R19),R19<Q19),AND(ISNUMBER(R19),ISNUMBER(S19),S19<R19),AND(ISNUMBER(S19),ISNUMBER(T19),T19<S19),AND(ISNUMBER(N19),ISNUMBER(O19),O19<N19)),"Urutan tanggal salah",IF(AND(ISNUMBER(Q19),ISNUMBER(R19),ISNUMBER(Y19),ABS(R19-Q19-Y19)>2),"S tanggal ≠ Sailing tercatat",IF(AND(ISNUMBER(Q19),ISNUMBER(O19),ABS(Q19-O19)>60),"Cek tahun laycan",IF(AND(ISNUMBER(Q19),ISNUMBER(N19),Q19<N19),"Berangkat sebelum laycan",IF(NOT(ISNUMBER(AE19)),"S belum ada","OK")))))) -> OK
A20: =IF(B20="","",ROW()-4) -> 16 | B20: KCL | C20: KCL 2nd | D20: 2022 | E20: Kanada | F20: Vancouver, Canada | G20: PKG Port , Gresik | H20: Aastar/Canpotex | I20: MV CL Iris | K20: 27500 | N20: 44789 | O20: 44789 | Q20: 44790 | R20: 44818 | U20: Selesai | X20: 16-Agu-2022 | Y20: 28 | Z20: LT History 2022–2024 | AA20: =IF(AND(ISNUMBER(L20),ISNUMBER(M20)),M20-L20,"") | AB20: =IF(AND(ISNUMBER(M20),ISNUMBER(P20)),P20-M20,"") | AC20: =IF(AND(ISNUMBER(L20),ISNUMBER(P20)),P20-L20,"") | AD20: =IF(AND(ISNUMBER(P20),ISNUMBER(Q20)),Q20-P20,"") | AE20: =IF(AND(ISNUMBER(Q20),ISNUMBER(R20)),R20-Q20,IF(ISNUMBER(Y20),Y20,"")) -> 28 | AF20: =IF(AND(ISNUMBER(R20),ISNUMBER(S20)),S20-R20,"") | AG20: =IF(AND(ISNUMBER(S20),ISNUMBER(T20)),T20-S20,"") | AH20: =IF(AND(ISNUMBER(L20),ISNUMBER(T20)),T20-L20,"") | AI20: =IF(AND(ISNUMBER(O20),ISNUMBER(Q20)),Q20-O20,"") -> 1 | AJ20: =IF(B20="","",COUNT(L20:M20,P20:T20)&"/7") -> 2/7 | AK20: =IF(B20="","",IF(OR(AND(ISNUMBER(L20),ISNUMBER(M20),M20<L20),AND(ISNUMBER(M20),ISNUMBER(P20),P20<M20),AND(ISNUMBER(P20),ISNUMBER(Q20),Q20<P20),AND(ISNUMBER(Q20),ISNUMBER(R20),R20<Q20),AND(ISNUMBER(R20),ISNUMBER(S20),S20<R20),AND(ISNUMBER(S20),ISNUMBER(T20),T20<S20),AND(ISNUMBER(N20),ISNUMBER(O20),O20<N20)),"Urutan tanggal salah",IF(AND(ISNUMBER(Q20),ISNUMBER(R20),ISNUMBER(Y20),ABS(R20-Q20-Y20)>2),"S tanggal ≠ Sailing tercatat",IF(AND(ISNUMBER(Q20),ISNUMBER(O20),ABS(Q20-O20)>60),"Cek tahun laycan",IF(AND(ISNUMBER(Q20),ISNUMBER(N20),Q20<N20),"Berangkat sebelum laycan",IF(NOT(ISNUMBER(AE20)),"S belum ada","OK")))))) -> OK
A21: =IF(B21="","",ROW()-4) -> 17 | B21: KCL | C21: KCL 1 st | D21: 2022 | E21: Russia | F21: Ust-Luga, Russia | G21: PKG Port , Gresik | H21: Eurochem Trading Middle East DMCC | I21: MV Gullwing | K21: 21537 | N21: 44754 | O21: 44754 | Q21: 44755 | R21: 44804 | U21: Selesai | Y21: 49 | Z21: LT History 2022–2024 | AA21: =IF(AND(ISNUMBER(L21),ISNUMBER(M21)),M21-L21,"") | AB21: =IF(AND(ISNUMBER(M21),ISNUMBER(P21)),P21-M21,"") | AC21: =IF(AND(ISNUMBER(L21),ISNUMBER(P21)),P21-L21,"") | AD21: =IF(AND(ISNUMBER(P21),ISNUMBER(Q21)),Q21-P21,"") | AE21: =IF(AND(ISNUMBER(Q21),ISNUMBER(R21)),R21-Q21,IF(ISNUMBER(Y21),Y21,"")) -> 49 | AF21: =IF(AND(ISNUMBER(R21),ISNUMBER(S21)),S21-R21,"") | AG21: =IF(AND(ISNUMBER(S21),ISNUMBER(T21)),T21-S21,"") | AH21: =IF(AND(ISNUMBER(L21),ISNUMBER(T21)),T21-L21,"") | AI21: =IF(AND(ISNUMBER(O21),ISNUMBER(Q21)),Q21-O21,"") -> 1 | AJ21: =IF(B21="","",COUNT(L21:M21,P21:T21)&"/7") -> 2/7 | AK21: =IF(B21="","",IF(OR(AND(ISNUMBER(L21),ISNUMBER(M21),M21<L21),AND(ISNUMBER(M21),ISNUMBER(P21),P21<M21),AND(ISNUMBER(P21),ISNUMBER(Q21),Q21<P21),AND(ISNUMBER(Q21),ISNUMBER(R21),R21<Q21),AND(ISNUMBER(R21),ISNUMBER(S21),S21<R21),AND(ISNUMBER(S21),ISNUMBER(T21),T21<S21),AND(ISNUMBER(N21),ISNUMBER(O21),O21<N21)),"Urutan tanggal salah",IF(AND(ISNUMBER(Q21),ISNUMBER(R21),ISNUMBER(Y21),ABS(R21-Q21-Y21)>2),"S tanggal ≠ Sailing tercatat",IF(AND(ISNUMBER(Q21),ISNUMBER(O21),ABS(Q21-O21)>60),"Cek tahun laycan",IF(AND(ISNUMBER(Q21),ISNUMBER(N21),Q21<N21),"Berangkat sebelum laycan",IF(NOT(ISNUMBER(AE21)),"S belum ada","OK")))))) -> OK
A22: =IF(B22="","",ROW()-4) -> 18 | B22: KCL | C22: KCL 2 nd | D22: 2022 | E22: Russia | F22: Murmansk, Russia | G22: PKG Port , Gresik | H22: Eurochem Trading Middle East DMCC | I22: MV ELISAR | K22: 33463 | N22: 44807 | O22: 44807 | Q22: 44811 | R22: 44851 | U22: Selesai | Y22: 40 | Z22: LT History 2022–2024 | AA22: =IF(AND(ISNUMBER(L22),ISNUMBER(M22)),M22-L22,"") | AB22: =IF(AND(ISNUMBER(M22),ISNUMBER(P22)),P22-M22,"") | AC22: =IF(AND(ISNUMBER(L22),ISNUMBER(P22)),P22-L22,"") | AD22: =IF(AND(ISNUMBER(P22),ISNUMBER(Q22)),Q22-P22,"") | AE22: =IF(AND(ISNUMBER(Q22),ISNUMBER(R22)),R22-Q22,IF(ISNUMBER(Y22),Y22,"")) -> 40 | AF22: =IF(AND(ISNUMBER(R22),ISNUMBER(S22)),S22-R22,"") | AG22: =IF(AND(ISNUMBER(S22),ISNUMBER(T22)),T22-S22,"") | AH22: =IF(AND(ISNUMBER(L22),ISNUMBER(T22)),T22-L22,"") | AI22: =IF(AND(ISNUMBER(O22),ISNUMBER(Q22)),Q22-O22,"") -> 4 | AJ22: =IF(B22="","",COUNT(L22:M22,P22:T22)&"/7") -> 2/7 | AK22: =IF(B22="","",IF(OR(AND(ISNUMBER(L22),ISNUMBER(M22),M22<L22),AND(ISNUMBER(M22),ISNUMBER(P22),P22<M22),AND(ISNUMBER(P22),ISNUMBER(Q22),Q22<P22),AND(ISNUMBER(Q22),ISNUMBER(R22),R22<Q22),AND(ISNUMBER(R22),ISNUMBER(S22),S22<R22),AND(ISNUMBER(S22),ISNUMBER(T22),T22<S22),AND(ISNUMBER(N22),ISNUMBER(O22),O22<N22)),"Urutan tanggal salah",IF(AND(ISNUMBER(Q22),ISNUMBER(R22),ISNUMBER(Y22),ABS(R22-Q22-Y22)>2),"S tanggal ≠ Sailing tercatat",IF(AND(ISNUMBER(Q22),ISNUMBER(O22),ABS(Q22-O22)>60),"Cek tahun laycan",IF(AND(ISNUMBER(Q22),ISNUMBER(N22),Q22<N22),"Berangkat sebelum laycan",IF(NOT(ISNUMBER(AE22)),"S belum ada","OK")))))) -> OK
A23: =IF(B23="","",ROW()-4) -> 19 | B23: KCL | C23: KCL | D23: 2022 | E23: Russia | F23: St Petersburg, Russia | G23: PKG Port , Gresik | H23: PJSC Uralkali | I23: MV Liberator | K23: 25670 | N23: 44842 | O23: 44842 | Q23: 44843 | R23: 44884 | U23: Selesai | X23: 8-Okt-2022 | Y23: 41 | Z23: LT History 2022–2024 | AA23: =IF(AND(ISNUMBER(L23),ISNUMBER(M23)),M23-L23,"") | AB23: =IF(AND(ISNUMBER(M23),ISNUMBER(P23)),P23-M23,"") | AC23: =IF(AND(ISNUMBER(L23),ISNUMBER(P23)),P23-L23,"") | AD23: =IF(AND(ISNUMBER(P23),ISNUMBER(Q23)),Q23-P23,"") | AE23: =IF(AND(ISNUMBER(Q23),ISNUMBER(R23)),R23-Q23,IF(ISNUMBER(Y23),Y23,"")) -> 41 | AF23: =IF(AND(ISNUMBER(R23),ISNUMBER(S23)),S23-R23,"") | AG23: =IF(AND(ISNUMBER(S23),ISNUMBER(T23)),T23-S23,"") | AH23: =IF(AND(ISNUMBER(L23),ISNUMBER(T23)),T23-L23,"") | AI23: =IF(AND(ISNUMBER(O23),ISNUMBER(Q23)),Q23-O23,"") -> 1 | AJ23: =IF(B23="","",COUNT(L23:M23,P23:T23)&"/7") -> 2/7 | AK23: =IF(B23="","",IF(OR(AND(ISNUMBER(L23),ISNUMBER(M23),M23<L23),AND(ISNUMBER(M23),ISNUMBER(P23),P23<M23),AND(ISNUMBER(P23),ISNUMBER(Q23),Q23<P23),AND(ISNUMBER(Q23),ISNUMBER(R23),R23<Q23),AND(ISNUMBER(R23),ISNUMBER(S23),S23<R23),AND(ISNUMBER(S23),ISNUMBER(T23),T23<S23),AND(ISNUMBER(N23),ISNUMBER(O23),O23<N23)),"Urutan tanggal salah",IF(AND(ISNUMBER(Q23),ISNUMBER(R23),ISNUMBER(Y23),ABS(R23-Q23-Y23)>2),"S tanggal ≠ Sailing tercatat",IF(AND(ISNUMBER(Q23),ISNUMBER(O23),ABS(Q23-O23)>60),"Cek tahun laycan",IF(AND(ISNUMBER(Q23),ISNUMBER(N23),Q23<N23),"Berangkat sebelum laycan",IF(NOT(ISNUMBER(AE23)),"S belum ada","OK")))))) -> OK
A24: =IF(B24="","",ROW()-4) -> 20 | B24: KCL | C24: KCL | D24: 2022 | E24: Belarusia | F24: St Petersburg, Russia | G24: PKG Port , Gresik | H24: JSC BPC/Fertilife FZE | I24: MV Almar | K24: 25000 | N24: 44848 | O24: 44851 | Q24: 44856 | R24: 44898 | U24: Selesai | X24: 14-17-Oct-2022 | Y24: 42 | Z24: LT History 2022–2024 | AA24: =IF(AND(ISNUMBER(L24),ISNUMBER(M24)),M24-L24,"") | AB24: =IF(AND(ISNUMBER(M24),ISNUMBER(P24)),P24-M24,"") | AC24: =IF(AND(ISNUMBER(L24),ISNUMBER(P24)),P24-L24,"") | AD24: =IF(AND(ISNUMBER(P24),ISNUMBER(Q24)),Q24-P24,"") | AE24: =IF(AND(ISNUMBER(Q24),ISNUMBER(R24)),R24-Q24,IF(ISNUMBER(Y24),Y24,"")) -> 42 | AF24: =IF(AND(ISNUMBER(R24),ISNUMBER(S24)),S24-R24,"") | AG24: =IF(AND(ISNUMBER(S24),ISNUMBER(T24)),T24-S24,"") | AH24: =IF(AND(ISNUMBER(L24),ISNUMBER(T24)),T24-L24,"") | AI24: =IF(AND(ISNUMBER(O24),ISNUMBER(Q24)),Q24-O24,"") -> 5 | AJ24: =IF(B24="","",COUNT(L24:M24,P24:T24)&"/7") -> 2/7 | AK24: =IF(B24="","",IF(OR(AND(ISNUMBER(L24),ISNUMBER(M24),M24<L24),AND(ISNUMBER(M24),ISNUMBER(P24),P24<M24),AND(ISNUMBER(P24),ISNUMBER(Q24),Q24<P24),AND(ISNUMBER(Q24),ISNUMBER(R24),R24<Q24),AND(ISNUMBER(R24),ISNUMBER(S24),S24<R24),AND(ISNUMBER(S24),ISNUMBER(T24),T24<S24),AND(ISNUMBER(N24),ISNUMBER(O24),O24<N24)),"Urutan tanggal salah",IF(AND(ISNUMBER(Q24),ISNUMBER(R24),ISNUMBER(Y24),ABS(R24-Q24-Y24)>2),"S tanggal ≠ Sailing tercatat",IF(AND(ISNUMBER(Q24),ISNUMBER(O24),ABS(Q24-O24)>60),"Cek tahun laycan",IF(AND(ISNUMBER(Q24),ISNUMBER(N24),Q24<N24),"Berangkat sebelum laycan",IF(NOT(ISNUMBER(AE24)),"S belum ada","OK")))))) -> OK
A25: =IF(B25="","",ROW()-4) -> 21 | B25: KCL | C25: KCL 1ST | D25: 2023 | E25: Jordan | F25: Aqaba, Jordan | G25: PKG Port , Gresik | H25: APC/ Clementcorp | I25: MV V Due | K25: 27500 | N25: 44904 | O25: 44911 | Q25: 44912 | R25: 44939 | U25: Selesai | X25: 9-16 DEC 22 | Y25: 27 | Z25: LT History 2022–2024 | AA25: =IF(AND(ISNUMBER(L25),ISNUMBER(M25)),M25-L25,"") | AB25: =IF(AND(ISNUMBER(M25),ISNUMBER(P25)),P25-M25,"") | AC25: =IF(AND(ISNUMBER(L25),ISNUMBER(P25)),P25-L25,"") | AD25: =IF(AND(ISNUMBER(P25),ISNUMBER(Q25)),Q25-P25,"") | AE25: =IF(AND(ISNUMBER(Q25),ISNUMBER(R25)),R25-Q25,IF(ISNUMBER(Y25),Y25,"")) -> 27 | AF25: =IF(AND(ISNUMBER(R25),ISNUMBER(S25)),S25-R25,"") | AG25: =IF(AND(ISNUMBER(S25),ISNUMBER(T25)),T25-S25,"") | AH25: =IF(AND(ISNUMBER(L25),ISNUMBER(T25)),T25-L25,"") | AI25: =IF(AND(ISNUMBER(O25),ISNUMBER(Q25)),Q25-O25,"") -> 1 | AJ25: =IF(B25="","",COUNT(L25:M25,P25:T25)&"/7") -> 2/7 | AK25: =IF(B25="","",IF(OR(AND(ISNUMBER(L25),ISNUMBER(M25),M25<L25),AND(ISNUMBER(M25),ISNUMBER(P25),P25<M25),AND(ISNUMBER(P25),ISNUMBER(Q25),Q25<P25),AND(ISNUMBER(Q25),ISNUMBER(R25),R25<Q25),AND(ISNUMBER(R25),ISNUMBER(S25),S25<R25),AND(ISNUMBER(S25),ISNUMBER(T25),T25<S25),AND(ISNUMBER(N25),ISNUMBER(O25),O25<N25)),"Urutan tanggal salah",IF(AND(ISNUMBER(Q25),ISNUMBER(R25),ISNUMBER(Y25),ABS(R25-Q25-Y25)>2),"S tanggal ≠ Sailing tercatat",IF(AND(ISNUMBER(Q25),ISNUMBER(O25),ABS(Q25-O25)>60),"Cek tahun laycan",IF(AND(ISNUMBER(Q25),ISNUMBER(N25),Q25<N25),"Berangkat sebelum laycan",IF(NOT(ISNUMBER(AE25)),"S belum ada","OK")))))) -> OK
A26: =IF(B26="","",ROW()-4) -> 22 | B26: KCL | C26: KCL 2ND | D26: 2023 | E26: Jordan | F26: Aqaba, Jordan | G26: PKG Port , Gresik | H26: APC/ Clementcorp | I26: MV Mount Owen | K26: 27500 | N26: 44967 | O26: 44977 | Q26: 44978 | R26: 45006 | U26: Selesai | X26: 10-20 Feb 23 | Y26: 28 | Z26: LT History 2022–2024 | AA26: =IF(AND(ISNUMBER(L26),ISNUMBER(M26)),M26-L26,"") | AB26: =IF(AND(ISNUMBER(M26),ISNUMBER(P26)),P26-M26,"") | AC26: =IF(AND(ISNUMBER(L26),ISNUMBER(P26)),P26-L26,"") | AD26: =IF(AND(ISNUMBER(P26),ISNUMBER(Q26)),Q26-P26,"") | AE26: =IF(AND(ISNUMBER(Q26),ISNUMBER(R26)),R26-Q26,IF(ISNUMBER(Y26),Y26,"")) -> 28 | AF26: =IF(AND(ISNUMBER(R26),ISNUMBER(S26)),S26-R26,"") | AG26: =IF(AND(ISNUMBER(S26),ISNUMBER(T26)),T26-S26,"") | AH26: =IF(AND(ISNUMBER(L26),ISNUMBER(T26)),T26-L26,"") | AI26: =IF(AND(ISNUMBER(O26),ISNUMBER(Q26)),Q26-O26,"") -> 1 | AJ26: =IF(B26="","",COUNT(L26:M26,P26:T26)&"/7") -> 2/7 | AK26: =IF(B26="","",IF(OR(AND(ISNUMBER(L26),ISNUMBER(M26),M26<L26),AND(ISNUMBER(M26),ISNUMBER(P26),P26<M26),AND(ISNUMBER(P26),ISNUMBER(Q26),Q26<P26),AND(ISNUMBER(Q26),ISNUMBER(R26),R26<Q26),AND(ISNUMBER(R26),ISNUMBER(S26),S26<R26),AND(ISNUMBER(S26),ISNUMBER(T26),T26<S26),AND(ISNUMBER(N26),ISNUMBER(O26),O26<N26)),"Urutan tanggal salah",IF(AND(ISNUMBER(Q26),ISNUMBER(R26),ISNUMBER(Y26),ABS(R26-Q26-Y26)>2),"S tanggal ≠ Sailing tercatat",IF(AND(ISNUMBER(Q26),ISNUMBER(O26),ABS(Q26-O26)>60),"Cek tahun laycan",IF(AND(ISNUMBER(Q26),ISNUMBER(N26),Q26<N26),"Berangkat sebelum laycan",IF(NOT(ISNUMBER(AE26)),"S belum ada","OK")))))) -> OK
A27: =IF(B27="","",ROW()-4) -> 23 | B27: KCL | C27: KCL 1st | D27: 2022 | E27: Kanada | F27: Vancouver,Canada | G27: PKG Port , Gresik | H27: Aastar/Canpotex | I27: MV Federal Island | K27: 27500 | N27: 44865 | O27: 44865 | Q27: 44867 | R27: 44895 | U27: Selesai | X27: 31-Okt-2022 | Y27: 28 | Z27: LT History 2022–2024 | AA27: =IF(AND(ISNUMBER(L27),ISNUMBER(M27)),M27-L27,"") | AB27: =IF(AND(ISNUMBER(M27),ISNUMBER(P27)),P27-M27,"") | AC27: =IF(AND(ISNUMBER(L27),ISNUMBER(P27)),P27-L27,"") | AD27: =IF(AND(ISNUMBER(P27),ISNUMBER(Q27)),Q27-P27,"") | AE27: =IF(AND(ISNUMBER(Q27),ISNUMBER(R27)),R27-Q27,IF(ISNUMBER(Y27),Y27,"")) -> 28 | AF27: =IF(AND(ISNUMBER(R27),ISNUMBER(S27)),S27-R27,"") | AG27: =IF(AND(ISNUMBER(S27),ISNUMBER(T27)),T27-S27,"") | AH27: =IF(AND(ISNUMBER(L27),ISNUMBER(T27)),T27-L27,"") | AI27: =IF(AND(ISNUMBER(O27),ISNUMBER(Q27)),Q27-O27,"") -> 2 | AJ27: =IF(B27="","",COUNT(L27:M27,P27:T27)&"/7") -> 2/7 | AK27: =IF(B27="","",IF(OR(AND(ISNUMBER(L27),ISNUMBER(M27),M27<L27),AND(ISNUMBER(M27),ISNUMBER(P27),P27<M27),AND(ISNUMBER(P27),ISNUMBER(Q27),Q27<P27),AND(ISNUMBER(Q27),ISNUMBER(R27),R27<Q27),AND(ISNUMBER(R27),ISNUMBER(S27),S27<R27),AND(ISNUMBER(S27),ISNUMBER(T27),T27<S27),AND(ISNUMBER(N27),ISNUMBER(O27),O27<N27)),"Urutan tanggal salah",IF(AND(ISNUMBER(Q27),ISNUMBER(R27),ISNUMBER(Y27),ABS(R27-Q27-Y27)>2),"S tanggal ≠ Sailing tercatat",IF(AND(ISNUMBER(Q27),ISNUMBER(O27),ABS(Q27-O27)>60),"Cek tahun laycan",IF(AND(ISNUMBER(Q27),ISNUMBER(N27),Q27<N27),"Berangkat sebelum laycan",IF(NOT(ISNUMBER(AE27)),"S belum ada","OK")))))) -> OK
A28: =IF(B28="","",ROW()-4) -> 24 | B28: KCL | C28: KCL 2nd | D28: 2023 | E28: Kanada | F28: Vancouver,Canada | G28: PKG Port , Gresik | H28: Aastar/Canpotex | I28: MV.Desert Dignity | K28: 27500 | N28: 44900 | O28: 44900 | Q28: 44902 | R28: 44931 | U28: Selesai | X28: 5-Des-2022 | Y28: 29 | Z28: LT History 2022–2024 | AA28: =IF(AND(ISNUMBER(L28),ISNUMBER(M28)),M28-L28,"") | AB28: =IF(AND(ISNUMBER(M28),ISNUMBER(P28)),P28-M28,"") | AC28: =IF(AND(ISNUMBER(L28),ISNUMBER(P28)),P28-L28,"") | AD28: =IF(AND(ISNUMBER(P28),ISNUMBER(Q28)),Q28-P28,"") | AE28: =IF(AND(ISNUMBER(Q28),ISNUMBER(R28)),R28-Q28,IF(ISNUMBER(Y28),Y28,"")) -> 29 | AF28: =IF(AND(ISNUMBER(R28),ISNUMBER(S28)),S28-R28,"") | AG28: =IF(AND(ISNUMBER(S28),ISNUMBER(T28)),T28-S28,"") | AH28: =IF(AND(ISNUMBER(L28),ISNUMBER(T28)),T28-L28,"") | AI28: =IF(AND(ISNUMBER(O28),ISNUMBER(Q28)),Q28-O28,"") -> 2 | AJ28: =IF(B28="","",COUNT(L28:M28,P28:T28)&"/7") -> 2/7 | AK28: =IF(B28="","",IF(OR(AND(ISNUMBER(L28),ISNUMBER(M28),M28<L28),AND(ISNUMBER(M28),ISNUMBER(P28),P28<M28),AND(ISNUMBER(P28),ISNUMBER(Q28),Q28<P28),AND(ISNUMBER(Q28),ISNUMBER(R28),R28<Q28),AND(ISNUMBER(R28),ISNUMBER(S28),S28<R28),AND(ISNUMBER(S28),ISNUMBER(T28),T28<S28),AND(ISNUMBER(N28),ISNUMBER(O28),O28<N28)),"Urutan tanggal salah",IF(AND(ISNUMBER(Q28),ISNUMBER(R28),ISNUMBER(Y28),ABS(R28-Q28-Y28)>2),"S tanggal ≠ Sailing tercatat",IF(AND(ISNUMBER(Q28),ISNUMBER(O28),ABS(Q28-O28)>60),"Cek tahun laycan",IF(AND(ISNUMBER(Q28),ISNUMBER(N28),Q28<N28),"Berangkat sebelum laycan",IF(NOT(ISNUMBER(AE28)),"S belum ada","OK")))))) -> OK
A29: =IF(B29="","",ROW()-4) -> 25 | B29: KCL | C29: KCL 3rd | D29: 2023 | E29: Kanada | F29: Vancouver,Canada | G29: PKG Port , Gresik | H29: Aastar/Canpotex | I29: MV.Ultra Lanigan | K29: 27500 | N29: 44915 | O29: 44915 | Q29: 44918 | R29: 44946 | U29: Selesai | X29: 20-Des-2022 | Y29: 28 | Z29: LT History 2022–2024 | AA29: =IF(AND(ISNUMBER(L29),ISNUMBER(M29)),M29-L29,"") | AB29: =IF(AND(ISNUMBER(M29),ISNUMBER(P29)),P29-M29,"") | AC29: =IF(AND(ISNUMBER(L29),ISNUMBER(P29)),P29-L29,"") | AD29: =IF(AND(ISNUMBER(P29),ISNUMBER(Q29)),Q29-P29,"") | AE29: =IF(AND(ISNUMBER(Q29),ISNUMBER(R29)),R29-Q29,IF(ISNUMBER(Y29),Y29,"")) -> 28 | AF29: =IF(AND(ISNUMBER(R29),ISNUMBER(S29)),S29-R29,"") | AG29: =IF(AND(ISNUMBER(S29),ISNUMBER(T29)),T29-S29,"") | AH29: =IF(AND(ISNUMBER(L29),ISNUMBER(T29)),T29-L29,"") | AI29: =IF(AND(ISNUMBER(O29),ISNUMBER(Q29)),Q29-O29,"") -> 3 | AJ29: =IF(B29="","",COUNT(L29:M29,P29:T29)&"/7") -> 2/7 | AK29: =IF(B29="","",IF(OR(AND(ISNUMBER(L29),ISNUMBER(M29),M29<L29),AND(ISNUMBER(M29),ISNUMBER(P29),P29<M29),AND(ISNUMBER(P29),ISNUMBER(Q29),Q29<P29),AND(ISNUMBER(Q29),ISNUMBER(R29),R29<Q29),AND(ISNUMBER(R29),ISNUMBER(S29),S29<R29),AND(ISNUMBER(S29),ISNUMBER(T29),T29<S29),AND(ISNUMBER(N29),ISNUMBER(O29),O29<N29)),"Urutan tanggal salah",IF(AND(ISNUMBER(Q29),ISNUMBER(R29),ISNUMBER(Y29),ABS(R29-Q29-Y29)>2),"S tanggal ≠ Sailing tercatat",IF(AND(ISNUMBER(Q29),ISNUMBER(O29),ABS(Q29-O29)>60),"Cek tahun laycan",IF(AND(ISNUMBER(Q29),ISNUMBER(N29),Q29<N29),"Berangkat sebelum laycan",IF(NOT(ISNUMBER(AE29)),"S belum ada","OK")))))) -> OK
A30: =IF(B30="","",ROW()-4) -> 26 | B30: KCL | C30: KCL 4th | D30: 2023 | E30: Kanada | F30: Vancouver,Canada | G30: PKG Port , Gresik | H30: Aastar/Canpotex | I30: MV Federal Illinois | K30: 27460 | N30: 44942 | O30: 44942 | Q30: 44943 | R30: 44971 | U30: Selesai | Y30: 28 | Z30: LT History 2022–2024 | AA30: =IF(AND(ISNUMBER(L30),ISNUMBER(M30)),M30-L30,"") | AB30: =IF(AND(ISNUMBER(M30),ISNUMBER(P30)),P30-M30,"") | AC30: =IF(AND(ISNUMBER(L30),ISNUMBER(P30)),P30-L30,"") | AD30: =IF(AND(ISNUMBER(P30),ISNUMBER(Q30)),Q30-P30,"") | AE30: =IF(AND(ISNUMBER(Q30),ISNUMBER(R30)),R30-Q30,IF(ISNUMBER(Y30),Y30,"")) -> 28 | AF30: =IF(AND(ISNUMBER(R30),ISNUMBER(S30)),S30-R30,"") | AG30: =IF(AND(ISNUMBER(S30),ISNUMBER(T30)),T30-S30,"") | AH30: =IF(AND(ISNUMBER(L30),ISNUMBER(T30)),T30-L30,"") | AI30: =IF(AND(ISNUMBER(O30),ISNUMBER(Q30)),Q30-O30,"") -> 1 | AJ30: =IF(B30="","",COUNT(L30:M30,P30:T30)&"/7") -> 2/7 | AK30: =IF(B30="","",IF(OR(AND(ISNUMBER(L30),ISNUMBER(M30),M30<L30),AND(ISNUMBER(M30),ISNUMBER(P30),P30<M30),AND(ISNUMBER(P30),ISNUMBER(Q30),Q30<P30),AND(ISNUMBER(Q30),ISNUMBER(R30),R30<Q30),AND(ISNUMBER(R30),ISNUMBER(S30),S30<R30),AND(ISNUMBER(S30),ISNUMBER(T30),T30<S30),AND(ISNUMBER(N30),ISNUMBER(O30),O30<N30)),"Urutan tanggal salah",IF(AND(ISNUMBER(Q30),ISNUMBER(R30),ISNUMBER(Y30),ABS(R30-Q30-Y30)>2),"S tanggal ≠ Sailing tercatat",IF(AND(ISNUMBER(Q30),ISNUMBER(O30),ABS(Q30-O30)>60),"Cek tahun laycan",IF(AND(ISNUMBER(Q30),ISNUMBER(N30),Q30<N30),"Berangkat sebelum laycan",IF(NOT(ISNUMBER(AE30)),"S belum ada","OK")))))) -> OK
A31: =IF(B31="","",ROW()-4) -> 27 | B31: KCL | C31: KCL 1st | D31: 2023 | E31: Belarusia | F31: St Petersburg, Russia | G31: PKG Port , Gresik | H31: JSC BPC/Fertilife FZE | I31: MV Ece nur bayraktar | K31: 27500 | N31: 44954 | O31: 44957 | Q31: 44958 | R31: 45000 | U31: Selesai | X31: 28-31 Jan 23 | Y31: 42 | Z31: LT History 2022–2024 | AA31: =IF(AND(ISNUMBER(L31),ISNUMBER(M31)),M31-L31,"") | AB31: =IF(AND(ISNUMBER(M31),ISNUMBER(P31)),P31-M31,"") | AC31: =IF(AND(ISNUMBER(L31),ISNUMBER(P31)),P31-L31,"") | AD31: =IF(AND(ISNUMBER(P31),ISNUMBER(Q31)),Q31-P31,"") | AE31: =IF(AND(ISNUMBER(Q31),ISNUMBER(R31)),R31-Q31,IF(ISNUMBER(Y31),Y31,"")) -> 42 | AF31: =IF(AND(ISNUMBER(R31),ISNUMBER(S31)),S31-R31,"") | AG31: =IF(AND(ISNUMBER(S31),ISNUMBER(T31)),T31-S31,"") | AH31: =IF(AND(ISNUMBER(L31),ISNUMBER(T31)),T31-L31,"") | AI31: =IF(AND(ISNUMBER(O31),ISNUMBER(Q31)),Q31-O31,"") -> 1 | AJ31: =IF(B31="","",COUNT(L31:M31,P31:T31)&"/7") -> 2/7 | AK31: =IF(B31="","",IF(OR(AND(ISNUMBER(L31),ISNUMBER(M31),M31<L31),AND(ISNUMBER(M31),ISNUMBER(P31),P31<M31),AND(ISNUMBER(P31),ISNUMBER(Q31),Q31<P31),AND(ISNUMBER(Q31),ISNUMBER(R31),R31<Q31),AND(ISNUMBER(R31),ISNUMBER(S31),S31<R31),AND(ISNUMBER(S31),ISNUMBER(T31),T31<S31),AND(ISNUMBER(N31),ISNUMBER(O31),O31<N31)),"Urutan tanggal salah",IF(AND(ISNUMBER(Q31),ISNUMBER(R31),ISNUMBER(Y31),ABS(R31-Q31-Y31)>2),"S tanggal ≠ Sailing tercatat",IF(AND(ISNUMBER(Q31),ISNUMBER(O31),ABS(Q31-O31)>60),"Cek tahun laycan",IF(AND(ISNUMBER(Q31),ISNUMBER(N31),Q31<N31),"Berangkat sebelum laycan",IF(NOT(ISNUMBER(AE31)),"S belum ada","OK")))))) -> OK
A32: =IF(B32="","",ROW()-4) -> 28 | B32: KCL | C32: KCL 2nd | D32: 2023 | E32: Belarusia | F32: St Petersburg, Russia | G32: PKG Port , Gresik | H32: JSC BPC/Fertilife FZE | I32: MV Gemini | K32: 26424 | N32: 45002 | O32: 45006 | Q32: 45007 | R32: 45057 | U32: Selesai | X32: 17-21 mar 23 | Y32: 50 | Z32: LT History 2022–2024 | AA32: =IF(AND(ISNUMBER(L32),ISNUMBER(M32)),M32-L32,"") | AB32: =IF(AND(ISNUMBER(M32),ISNUMBER(P32)),P32-M32,"") | AC32: =IF(AND(ISNUMBER(L32),ISNUMBER(P32)),P32-L32,"") | AD32: =IF(AND(ISNUMBER(P32),ISNUMBER(Q32)),Q32-P32,"") | AE32: =IF(AND(ISNUMBER(Q32),ISNUMBER(R32)),R32-Q32,IF(ISNUMBER(Y32),Y32,"")) -> 50 | AF32: =IF(AND(ISNUMBER(R32),ISNUMBER(S32)),S32-R32,"") | AG32: =IF(AND(ISNUMBER(S32),ISNUMBER(T32)),T32-S32,"") | AH32: =IF(AND(ISNUMBER(L32),ISNUMBER(T32)),T32-L32,"") | AI32: =IF(AND(ISNUMBER(O32),ISNUMBER(Q32)),Q32-O32,"") -> 1 | AJ32: =IF(B32="","",COUNT(L32:M32,P32:T32)&"/7") -> 2/7 | AK32: =IF(B32="","",IF(OR(AND(ISNUMBER(L32),ISNUMBER(M32),M32<L32),AND(ISNUMBER(M32),ISNUMBER(P32),P32<M32),AND(ISNUMBER(P32),ISNUMBER(Q32),Q32<P32),AND(ISNUMBER(Q32),ISNUMBER(R32),R32<Q32),AND(ISNUMBER(R32),ISNUMBER(S32),S32<R32),AND(ISNUMBER(S32),ISNUMBER(T32),T32<S32),AND(ISNUMBER(N32),ISNUMBER(O32),O32<N32)),"Urutan tanggal salah",IF(AND(ISNUMBER(Q32),ISNUMBER(R32),ISNUMBER(Y32),ABS(R32-Q32-Y32)>2),"S tanggal ≠ Sailing tercatat",IF(AND(ISNUMBER(Q32),ISNUMBER(O32),ABS(Q32-O32)>60),"Cek tahun laycan",IF(AND(ISNUMBER(Q32),ISNUMBER(N32),Q32<N32),"Berangkat sebelum laycan",IF(NOT(ISNUMBER(AE32)),"S belum ada","OK")))))) -> OK
A33: =IF(B33="","",ROW()-4) -> 29 | B33: KCL | C33: KCL 3rd | D33: 2023 | E33: Belarusia | F33: St Petersburg, Russia | G33: PKG Port , Gresik | H33: JSC BPC/Fertilife FZE | I33: MV IDC Pearl | K33: 27500 | N33: 45044 | O33: 45051 | Q33: 45052 | R33: 45096 | U33: Selesai | X33: 28 Apr - 05 Mei 23 | Y33: 44 | Z33: LT History 2022–2024 | AA33: =IF(AND(ISNUMBER(L33),ISNUMBER(M33)),M33-L33,"") | AB33: =IF(AND(ISNUMBER(M33),ISNUMBER(P33)),P33-M33,"") | AC33: =IF(AND(ISNUMBER(L33),ISNUMBER(P33)),P33-L33,"") | AD33: =IF(AND(ISNUMBER(P33),ISNUMBER(Q33)),Q33-P33,"") | AE33: =IF(AND(ISNUMBER(Q33),ISNUMBER(R33)),R33-Q33,IF(ISNUMBER(Y33),Y33,"")) -> 44 | AF33: =IF(AND(ISNUMBER(R33),ISNUMBER(S33)),S33-R33,"") | AG33: =IF(AND(ISNUMBER(S33),ISNUMBER(T33)),T33-S33,"") | AH33: =IF(AND(ISNUMBER(L33),ISNUMBER(T33)),T33-L33,"") | AI33: =IF(AND(ISNUMBER(O33),ISNUMBER(Q33)),Q33-O33,"") -> 1 | AJ33: =IF(B33="","",COUNT(L33:M33,P33:T33)&"/7") -> 2/7 | AK33: =IF(B33="","",IF(OR(AND(ISNUMBER(L33),ISNUMBER(M33),M33<L33),AND(ISNUMBER(M33),ISNUMBER(P33),P33<M33),AND(ISNUMBER(P33),ISNUMBER(Q33),Q33<P33),AND(ISNUMBER(Q33),ISNUMBER(R33),R33<Q33),AND(ISNUMBER(R33),ISNUMBER(S33),S33<R33),AND(ISNUMBER(S33),ISNUMBER(T33),T33<S33),AND(ISNUMBER(N33),ISNUMBER(O33),O33<N33)),"Urutan tanggal salah",IF(AND(ISNUMBER(Q33),ISNUMBER(R33),ISNUMBER(Y33),ABS(R33-Q33-Y33)>2),"S tanggal ≠ Sailing tercatat",IF(AND(ISNUMBER(Q33),ISNUMBER(O33),ABS(Q33-O33)>60),"Cek tahun laycan",IF(AND(ISNUMBER(Q33),ISNUMBER(N33),Q33<N33),"Berangkat sebelum laycan",IF(NOT(ISNUMBER(AE33)),"S belum ada","OK")))))) -> OK
A34: =IF(B34="","",ROW()-4) -> 30 | B34: KCL | C34: KCL 4th | D34: 2023 | E34: Belarusia | F34: St Petersburg, Russia | G34: PKG Port , Gresik | H34: JSC BPC/Fertilife FZE | I34: MV Vantage Reef | K34: 27500 | N34: 45077 | O34: 45080 | Q34: 45081 | R34: 45124 | U34: Selesai | X34: 31 Mei - 03 Juni 23 | Y34: 43 | Z34: LT History 2022–2024 | AA34: =IF(AND(ISNUMBER(L34),ISNUMBER(M34)),M34-L34,"") | AB34: =IF(AND(ISNUMBER(M34),ISNUMBER(P34)),P34-M34,"") | AC34: =IF(AND(ISNUMBER(L34),ISNUMBER(P34)),P34-L34,"") | AD34: =IF(AND(ISNUMBER(P34),ISNUMBER(Q34)),Q34-P34,"") | AE34: =IF(AND(ISNUMBER(Q34),ISNUMBER(R34)),R34-Q34,IF(ISNUMBER(Y34),Y34,"")) -> 43 | AF34: =IF(AND(ISNUMBER(R34),ISNUMBER(S34)),S34-R34,"") | AG34: =IF(AND(ISNUMBER(S34),ISNUMBER(T34)),T34-S34,"") | AH34: =IF(AND(ISNUMBER(L34),ISNUMBER(T34)),T34-L34,"") | AI34: =IF(AND(ISNUMBER(O34),ISNUMBER(Q34)),Q34-O34,"") -> 1 | AJ34: =IF(B34="","",COUNT(L34:M34,P34:T34)&"/7") -> 2/7 | AK34: =IF(B34="","",IF(OR(AND(ISNUMBER(L34),ISNUMBER(M34),M34<L34),AND(ISNUMBER(M34),ISNUMBER(P34),P34<M34),AND(ISNUMBER(P34),ISNUMBER(Q34),Q34<P34),AND(ISNUMBER(Q34),ISNUMBER(R34),R34<Q34),AND(ISNUMBER(R34),ISNUMBER(S34),S34<R34),AND(ISNUMBER(S34),ISNUMBER(T34),T34<S34),AND(ISNUMBER(N34),ISNUMBER(O34),O34<N34)),"Urutan tanggal salah",IF(AND(ISNUMBER(Q34),ISNUMBER(R34),ISNUMBER(Y34),ABS(R34-Q34-Y34)>2),"S tanggal ≠ Sailing tercatat",IF(AND(ISNUMBER(Q34),ISNUMBER(O34),ABS(Q34-O34)>60),"Cek tahun laycan",IF(AND(ISNUMBER(Q34),ISNUMBER(N34),Q34<N34),"Berangkat sebelum laycan",IF(NOT(ISNUMBER(AE34)),"S belum ada","OK")))))) -> OK
A35: =IF(B35="","",ROW()-4) -> 31 | B35: KCL | C35: KCL FG | D35: 2023 | E35: Belarusia | F35: Yantai, China | G35: PKG Port , Gresik | H35: JSC BPC/Fertilife FZE | I35: MV Galaxy Ocean | K35: 5500 | N35: 45087 | O35: 45087 | Q35: 45088 | R35: 45100 | U35: Selesai | Y35: 12 | Z35: LT History 2022–2024 | AA35: =IF(AND(ISNUMBER(L35),ISNUMBER(M35)),M35-L35,"") | AB35: =IF(AND(ISNUMBER(M35),ISNUMBER(P35)),P35-M35,"") | AC35: =IF(AND(ISNUMBER(L35),ISNUMBER(P35)),P35-L35,"") | AD35: =IF(AND(ISNUMBER(P35),ISNUMBER(Q35)),Q35-P35,"") | AE35: =IF(AND(ISNUMBER(Q35),ISNUMBER(R35)),R35-Q35,IF(ISNUMBER(Y35),Y35,"")) -> 12 | AF35: =IF(AND(ISNUMBER(R35),ISNUMBER(S35)),S35-R35,"") | AG35: =IF(AND(ISNUMBER(S35),ISNUMBER(T35)),T35-S35,"") | AH35: =IF(AND(ISNUMBER(L35),ISNUMBER(T35)),T35-L35,"") | AI35: =IF(AND(ISNUMBER(O35),ISNUMBER(Q35)),Q35-O35,"") -> 1 | AJ35: =IF(B35="","",COUNT(L35:M35,P35:T35)&"/7") -> 2/7 | AK35: =IF(B35="","",IF(OR(AND(ISNUMBER(L35),ISNUMBER(M35),M35<L35),AND(ISNUMBER(M35),ISNUMBER(P35),P35<M35),AND(ISNUMBER(P35),ISNUMBER(Q35),Q35<P35),AND(ISNUMBER(Q35),ISNUMBER(R35),R35<Q35),AND(ISNUMBER(R35),ISNUMBER(S35),S35<R35),AND(ISNUMBER(S35),ISNUMBER(T35),T35<S35),AND(ISNUMBER(N35),ISNUMBER(O35),O35<N35)),"Urutan tanggal salah",IF(AND(ISNUMBER(Q35),ISNUMBER(R35),ISNUMBER(Y35),ABS(R35-Q35-Y35)>2),"S tanggal ≠ Sailing tercatat",IF(AND(ISNUMBER(Q35),ISNUMBER(O35),ABS(Q35-O35)>60),"Cek tahun laycan",IF(AND(ISNUMBER(Q35),ISNUMBER(N35),Q35<N35),"Berangkat sebelum laycan",IF(NOT(ISNUMBER(AE35)),"S belum ada","OK")))))) -> OK
A36: =IF(B36="","",ROW()-4) -> 32 | B36: KCL | C36: KCL 1 st | D36: 2023 | E36: Russia | F36: Kavkaz, Russia | G36: PKG Port , Gresik | H36: Eurochem Trading Middle East DMCC | I36: MV DSM London | K36: 27500 | N36: 45051 | O36: 45054 | Q36: 45056 | R36: 45095 | U36: Selesai | X36: 5-8 Mei 23 | Y36: 39 | Z36: LT History 2022–2024 | AA36: =IF(AND(ISNUMBER(L36),ISNUMBER(M36)),M36-L36,"") | AB36: =IF(AND(ISNUMBER(M36),ISNUMBER(P36)),P36-M36,"") | AC36: =IF(AND(ISNUMBER(L36),ISNUMBER(P36)),P36-L36,"") | AD36: =IF(AND(ISNUMBER(P36),ISNUMBER(Q36)),Q36-P36,"") | AE36: =IF(AND(ISNUMBER(Q36),ISNUMBER(R36)),R36-Q36,IF(ISNUMBER(Y36),Y36,"")) -> 39 | AF36: =IF(AND(ISNUMBER(R36),ISNUMBER(S36)),S36-R36,"") | AG36: =IF(AND(ISNUMBER(S36),ISNUMBER(T36)),T36-S36,"") | AH36: =IF(AND(ISNUMBER(L36),ISNUMBER(T36)),T36-L36,"") | AI36: =IF(AND(ISNUMBER(O36),ISNUMBER(Q36)),Q36-O36,"") -> 2 | AJ36: =IF(B36="","",COUNT(L36:M36,P36:T36)&"/7") -> 2/7 | AK36: =IF(B36="","",IF(OR(AND(ISNUMBER(L36),ISNUMBER(M36),M36<L36),AND(ISNUMBER(M36),ISNUMBER(P36),P36<M36),AND(ISNUMBER(P36),ISNUMBER(Q36),Q36<P36),AND(ISNUMBER(Q36),ISNUMBER(R36),R36<Q36),AND(ISNUMBER(R36),ISNUMBER(S36),S36<R36),AND(ISNUMBER(S36),ISNUMBER(T36),T36<S36),AND(ISNUMBER(N36),ISNUMBER(O36),O36<N36)),"Urutan tanggal salah",IF(AND(ISNUMBER(Q36),ISNUMBER(R36),ISNUMBER(Y36),ABS(R36-Q36-Y36)>2),"S tanggal ≠ Sailing tercatat",IF(AND(ISNUMBER(Q36),ISNUMBER(O36),ABS(Q36-O36)>60),"Cek tahun laycan",IF(AND(ISNUMBER(Q36),ISNUMBER(N36),Q36<N36),"Berangkat sebelum laycan",IF(NOT(ISNUMBER(AE36)),"S belum ada","OK")))))) -> OK
A37: =IF(B37="","",ROW()-4) -> 33 | B37: KCL | C37: KCL 2 nd | D37: 2023 | E37: Russia | F37: Ust-Luga, Russia | G37: PKG Port , Gresik | H37: Eurochem Trading Middle East DMCC | I37: MV Navi Moon | K37: 10200 | N37: 45025 | O37: 45026 | Q37: 45026 | R37: 45069 | U37: Selesai | X37: 9-10 Apr 23 | Y37: 43 | Z37: LT History 2022–2024 | AA37: =IF(AND(ISNUMBER(L37),ISNUMBER(M37)),M37-L37,"") | AB37: =IF(AND(ISNUMBER(M37),ISNUMBER(P37)),P37-M37,"") | AC37: =IF(AND(ISNUMBER(L37),ISNUMBER(P37)),P37-L37,"") | AD37: =IF(AND(ISNUMBER(P37),ISNUMBER(Q37)),Q37-P37,"") | AE37: =IF(AND(ISNUMBER(Q37),ISNUMBER(R37)),R37-Q37,IF(ISNUMBER(Y37),Y37,"")) -> 43 | AF37: =IF(AND(ISNUMBER(R37),ISNUMBER(S37)),S37-R37,"") | AG37: =IF(AND(ISNUMBER(S37),ISNUMBER(T37)),T37-S37,"") | AH37: =IF(AND(ISNUMBER(L37),ISNUMBER(T37)),T37-L37,"") | AI37: =IF(AND(ISNUMBER(O37),ISNUMBER(Q37)),Q37-O37,"") -> 0 | AJ37: =IF(B37="","",COUNT(L37:M37,P37:T37)&"/7") -> 2/7 | AK37: =IF(B37="","",IF(OR(AND(ISNUMBER(L37),ISNUMBER(M37),M37<L37),AND(ISNUMBER(M37),ISNUMBER(P37),P37<M37),AND(ISNUMBER(P37),ISNUMBER(Q37),Q37<P37),AND(ISNUMBER(Q37),ISNUMBER(R37),R37<Q37),AND(ISNUMBER(R37),ISNUMBER(S37),S37<R37),AND(ISNUMBER(S37),ISNUMBER(T37),T37<S37),AND(ISNUMBER(N37),ISNUMBER(O37),O37<N37)),"Urutan tanggal salah",IF(AND(ISNUMBER(Q37),ISNUMBER(R37),ISNUMBER(Y37),ABS(R37-Q37-Y37)>2),"S tanggal ≠ Sailing tercatat",IF(AND(ISNUMBER(Q37),ISNUMBER(O37),ABS(Q37-O37)>60),"Cek tahun laycan",IF(AND(ISNUMBER(Q37),ISNUMBER(N37),Q37<N37),"Berangkat sebelum laycan",IF(NOT(ISNUMBER(AE37)),"S belum ada","OK")))))) -> OK
A38: =IF(B38="","",ROW()-4) -> 34 | B38: KCL | C38: KCL 3 rd | D38: 2023 | E38: Russia | F38: Ust Luga, Russia | G38: PKG Port , Gresik | H38: Eurochem Trading Middle East DMCC | I38: MV Devbulk Sinem | K38: 27500 | N38: 45089 | O38: 45091 | Q38: 45092 | R38: 45135 | U38: Selesai | X38: 12-14 Juni 23 | Y38: 43 | Z38: LT History 2022–2024 | AA38: =IF(AND(ISNUMBER(L38),ISNUMBER(M38)),M38-L38,"") | AB38: =IF(AND(ISNUMBER(M38),ISNUMBER(P38)),P38-M38,"") | AC38: =IF(AND(ISNUMBER(L38),ISNUMBER(P38)),P38-L38,"") | AD38: =IF(AND(ISNUMBER(P38),ISNUMBER(Q38)),Q38-P38,"") | AE38: =IF(AND(ISNUMBER(Q38),ISNUMBER(R38)),R38-Q38,IF(ISNUMBER(Y38),Y38,"")) -> 43 | AF38: =IF(AND(ISNUMBER(R38),ISNUMBER(S38)),S38-R38,"") | AG38: =IF(AND(ISNUMBER(S38),ISNUMBER(T38)),T38-S38,"") | AH38: =IF(AND(ISNUMBER(L38),ISNUMBER(T38)),T38-L38,"") | AI38: =IF(AND(ISNUMBER(O38),ISNUMBER(Q38)),Q38-O38,"") -> 1 | AJ38: =IF(B38="","",COUNT(L38:M38,P38:T38)&"/7") -> 2/7 | AK38: =IF(B38="","",IF(OR(AND(ISNUMBER(L38),ISNUMBER(M38),M38<L38),AND(ISNUMBER(M38),ISNUMBER(P38),P38<M38),AND(ISNUMBER(P38),ISNUMBER(Q38),Q38<P38),AND(ISNUMBER(Q38),ISNUMBER(R38),R38<Q38),AND(ISNUMBER(R38),ISNUMBER(S38),S38<R38),AND(ISNUMBER(S38),ISNUMBER(T38),T38<S38),AND(ISNUMBER(N38),ISNUMBER(O38),O38<N38)),"Urutan tanggal salah",IF(AND(ISNUMBER(Q38),ISNUMBER(R38),ISNUMBER(Y38),ABS(R38-Q38-Y38)>2),"S tanggal ≠ Sailing tercatat",IF(AND(ISNUMBER(Q38),ISNUMBER(O38),ABS(Q38-O38)>60),"Cek tahun laycan",IF(AND(ISNUMBER(Q38),ISNUMBER(N38),Q38<N38),"Berangkat sebelum laycan",IF(NOT(ISNUMBER(AE38)),"S belum ada","OK")))))) -> OK
A39: =IF(B39="","",ROW()-4) -> 35 | B39: KCL | C39: KCL 4 th | D39: 2023 | E39: Russia | F39: Ust Luga, Russia | G39: PKG Port , Gresik | H39: Eurochem Trading Middle East DMCC | I39: MV Valsamitis | K39: 27500 | N39: 45099 | O39: 45101 | Q39: 45103 | R39: 45145 | U39: Selesai | X39: 22-24 Juni 23 | Y39: 42 | Z39: LT History 2022–2024 | AA39: =IF(AND(ISNUMBER(L39),ISNUMBER(M39)),M39-L39,"") | AB39: =IF(AND(ISNUMBER(M39),ISNUMBER(P39)),P39-M39,"") | AC39: =IF(AND(ISNUMBER(L39),ISNUMBER(P39)),P39-L39,"") | AD39: =IF(AND(ISNUMBER(P39),ISNUMBER(Q39)),Q39-P39,"") | AE39: =IF(AND(ISNUMBER(Q39),ISNUMBER(R39)),R39-Q39,IF(ISNUMBER(Y39),Y39,"")) -> 42 | AF39: =IF(AND(ISNUMBER(R39),ISNUMBER(S39)),S39-R39,"") | AG39: =IF(AND(ISNUMBER(S39),ISNUMBER(T39)),T39-S39,"") | AH39: =IF(AND(ISNUMBER(L39),ISNUMBER(T39)),T39-L39,"") | AI39: =IF(AND(ISNUMBER(O39),ISNUMBER(Q39)),Q39-O39,"") -> 2 | AJ39: =IF(B39="","",COUNT(L39:M39,P39:T39)&"/7") -> 2/7 | AK39: =IF(B39="","",IF(OR(AND(ISNUMBER(L39),ISNUMBER(M39),M39<L39),AND(ISNUMBER(M39),ISNUMBER(P39),P39<M39),AND(ISNUMBER(P39),ISNUMBER(Q39),Q39<P39),AND(ISNUMBER(Q39),ISNUMBER(R39),R39<Q39),AND(ISNUMBER(R39),ISNUMBER(S39),S39<R39),AND(ISNUMBER(S39),ISNUMBER(T39),T39<S39),AND(ISNUMBER(N39),ISNUMBER(O39),O39<N39)),"Urutan tanggal salah",IF(AND(ISNUMBER(Q39),ISNUMBER(R39),ISNUMBER(Y39),ABS(R39-Q39-Y39)>2),"S tanggal ≠ Sailing tercatat",IF(AND(ISNUMBER(Q39),ISNUMBER(O39),ABS(Q39-O39)>60),"Cek tahun laycan",IF(AND(ISNUMBER(Q39),ISNUMBER(N39),Q39<N39),"Berangkat sebelum laycan",IF(NOT(ISNUMBER(AE39)),"S belum ada","OK")))))) -> OK
A40: =IF(B40="","",ROW()-4) -> 36 | B40: KCL | C40: KCL 5 th | D40: 2023 | E40: Russia | F40: Ust Luga, Russia | G40: PKG Port , Gresik | H40: Eurochem Trading Middle East DMCC | I40: MV NYMPHI | K40: 27500 | N40: 45112 | O40: 45116 | Q40: 45117 | R40: 45161 | U40: Selesai | X40: 5-9 July 23 | Y40: 44 | Z40: LT History 2022–2024 | AA40: =IF(AND(ISNUMBER(L40),ISNUMBER(M40)),M40-L40,"") | AB40: =IF(AND(ISNUMBER(M40),ISNUMBER(P40)),P40-M40,"") | AC40: =IF(AND(ISNUMBER(L40),ISNUMBER(P40)),P40-L40,"") | AD40: =IF(AND(ISNUMBER(P40),ISNUMBER(Q40)),Q40-P40,"") | AE40: =IF(AND(ISNUMBER(Q40),ISNUMBER(R40)),R40-Q40,IF(ISNUMBER(Y40),Y40,"")) -> 44 | AF40: =IF(AND(ISNUMBER(R40),ISNUMBER(S40)),S40-R40,"") | AG40: =IF(AND(ISNUMBER(S40),ISNUMBER(T40)),T40-S40,"") | AH40: =IF(AND(ISNUMBER(L40),ISNUMBER(T40)),T40-L40,"") | AI40: =IF(AND(ISNUMBER(O40),ISNUMBER(Q40)),Q40-O40,"") -> 1 | AJ40: =IF(B40="","",COUNT(L40:M40,P40:T40)&"/7") -> 2/7 | AK40: =IF(B40="","",IF(OR(AND(ISNUMBER(L40),ISNUMBER(M40),M40<L40),AND(ISNUMBER(M40),ISNUMBER(P40),P40<M40),AND(ISNUMBER(P40),ISNUMBER(Q40),Q40<P40),AND(ISNUMBER(Q40),ISNUMBER(R40),R40<Q40),AND(ISNUMBER(R40),ISNUMBER(S40),S40<R40),AND(ISNUMBER(S40),ISNUMBER(T40),T40<S40),AND(ISNUMBER(N40),ISNUMBER(O40),O40<N40)),"Urutan tanggal salah",IF(AND(ISNUMBER(Q40),ISNUMBER(R40),ISNUMBER(Y40),ABS(R40-Q40-Y40)>2),"S tanggal ≠ Sailing tercatat",IF(AND(ISNUMBER(Q40),ISNUMBER(O40),ABS(Q40-O40)>60),"Cek tahun laycan",IF(AND(ISNUMBER(Q40),ISNUMBER(N40),Q40<N40),"Berangkat sebelum laycan",IF(NOT(ISNUMBER(AE40)),"S belum ada","OK")))))) -> OK
...

Sheet Statistik
A1: Statistik Lead Time & Konsumsi per Bahan — PKG
A2: Dihitung otomatis dari Log_Kargo dan Data_CR. Status kesiapan: n ≥ 20 Siap · 10–19 Terbatas · < 10 Belum.
A4: S Sailing (⑤−④)
A5: Bahan | B5: n | C5: Rata-rata | D5: Maks | E5: Simp. baku | F5: Persentil 90 | G5: Kesiapan
