Workbook

Sheet PANDUAN
B1: Templat Pengisian Data Dalops 2026 · PIM
B2: PT Pupuk Iskandar Muda · untuk dashboard CAK PRI PI Group v3
B4: Arti warna sel
B5: contoh | C5: Kuning, teks biru: DIISI oleh Anper
B6: contoh | C6: Abu-abu: rumus otomatis — jangan diubah (kecuali disebut "boleh ditimpa")
B7: contoh | C7: Putih: kunci baris (tanggal, material, unit) — sudah disiapkan
B9: Langkah pengisian
B10: 1. Sheet profil: isi posisi_data (tanggal realisasi terakhir), tanggal_update, dosis, produk NPK, konteks. Kolom "jenis" di semua sheet otomatis mengikuti posisi_data.
B11: 2. Ganti nama unit, pemasok gas, dan sumber pasokan contoh dengan nama sebenarnya (Ctrl+H, ganti di seluruh workbook agar konsisten antarsheet).
B12: 3. Isi sheet harian: angka Realisasi sampai posisi_data, lalu angka Rencana sampai 31 Desember. Stok awal cukup diisi pada 1 Januari.
B13: 4. Isi jadwal_kapal untuk semua kargo 2026 (tiba, dalam pelayaran, rencana). Isi perubahan_versi bila ETA/volume berubah dari versi sebelumnya.
B14: 5. Isi status_unit (posisi hari ini), parameter_kri (safety stock & deadstock Kesepakatan PI Group), cons_rate, sumber_pasokan.
B15: 6. Periksa tabel "Cek otomatis" di bawah: semua harus 0 / OK sebelum dikirim.
B16: 7. Simpan sebagai .xlsx dengan nama mengandung kode entitas, mis. Dalops_PIM_2026_posisi_<tanggal>.xlsx, lalu muat lewat tombol "Muat Data" di dashboard.
B17: Jangan mengganti nama sheet, nama kolom di baris 1, atau menyisipkan baris di atas header. Sheet PANDUAN dan kolom cek_selisih_t tidak dibaca dashboard.
B19: Isi tiap sheet
B20: Sheet | C20: Isi | D20: Modul dashboard
B21: profil | C21: Identitas, posisi data, dosis, konteks | D21: Semua modul
B22: harian_gas | C22: Pasokan harian per pemasok (BBTUD) vs kontrak | D22: 01, 08, 09
B23: ringkasan_gas | C23: Total pasokan (otomatis), kebutuhan, pemakaian, konsumsi spesifik | D23: 01, 02, 05, 09
B24: harian_bahan_baku | C24: Neraca harian amoniak, KCl, DAP, ZA, clay | D24: 01, 05, 06, 08, 09
B25: harian_produksi | C25: Produksi harian per unit amoniak/urea/NPK | D25: 02, 08, 09, 11, 12
B26: rkap_bulanan | C26: RKAP 2026 per unit per bulan | D26: 02
B27: stok_produk_lini1 | C27: Stok, masuk, penyaluran produk di gudang Lini I | D27: 03
B28: jadwal_kapal | C28: Seluruh kargo 2026 beserta ETA awal & terkini | D28: 01, 04, 05, 06
B29: perubahan_versi | C29: Perubahan ETA/volume antar-versi master | D29: 07
B30: status_unit | C30: Unit berhenti/turnaround/trip pada posisi data | D30: 01, 02, 13
B31: parameter_kri | C31: Safety stock & deadstock (Kesepakatan PI Group), ambang KRI | D31: 01, 13
... B35: ambang_siaga | C35: Pemicu Siaga 1–3 dan tindakannya | D35: 13
B37: Contoh pengisian (format yang diharapkan; angka contoh)
B38: harian_bahan_baku
B39: tanggal | C39: jenis | D39: kode_material | E39: material | F39: stok_awal_t | G39: kedatangan_t | H39: produksi_sendiri_t | I39: pemakaian_t | J39: dijual_transfer_t | K39: stok_akhir_t
B40: 46303 | C40: Realisasi | D40: KCL | E40: KCl | F40: 14467.6 | G40: 0 | H40: 0 | I40: 217.6 | J40: 0 | K40: 14250
B42: harian_gas
B43: tanggal | C43: jenis | D43: pemasok | E43: kontrak_bbtud | F43: pasokan_bbtud
B44: 46303 | C44: Realisasi | D44: Pemasok Gas A · Blok Hulu 4 | E44: 150 | F44: 115.7
B46: jadwal_kapal
B47: material | C47: negara_asal | D47: pelabuhan_muat | E47: nama_kapal | F47: volume_t | G47: eta_terkini | H47: eta_awal | I47: status | J47: jarak_nm | K47: waktu_layar_hari | L47: lewat_hormuz
B48: KCl | C48: Kanada | D48: Vancouver | E48: MV Nama Kapal | F48: 31400 | G48: 46314 | H48: 46298 | I48: Terlambat | J48: 8150 | K48: 27.2 | L48: Tidak
B49: Baris contoh di atas hanya ilustrasi format, tidak dibaca dashboard.
...

Sheet profil
A1: parameter | B1: nilai | C1: keterangan
A2: kode | B2: PIM | C2: Jangan diubah. Dipakai dashboard untuk mengenali entitas.
A3: nama | B3: PT Pupuk Iskandar Muda | C3: Nama resmi perusahaan.
A4: lokasi | B4: Lhokseumawe, Aceh | C4: Kota, provinsi lokasi pabrik.
A5: pelabuhan_bongkar | B5: Pelabuhan Krueng Geukueh | C5: Pelabuhan bongkar impor. Periksa: nama dari data dummy.
A6: pelabuhan_lat | B6: 5.25 | C6: Lintang pelabuhan bongkar (derajat desimal, selatan negatif).
A7: pelabuhan_lon | B7: 97.03 | C7: Bujur pelabuhan bongkar (derajat desimal).
A8: warna_aksen | C8: Kode warna brand, mis. #F5A623. Boleh dikosongkan.
A9: posisi_data | C9: WAJIB. Tanggal realisasi terakhir. Kolom "jenis" di semua sheet mengikuti tanggal ini.
A10: tanggal_update | C10: Tanggal berkas ini disusun.
A11: periode_konsumsi | B11: =IF(B9="","",DAY(B9-29)&" "&CHOOSE(MONTH(B9-29),"Jan","Feb","Mar","Apr","Mei","Jun","Jul","Agu","Sep","Okt","Nov","Des")&" – "&DAY(B9)&" "&CHOOSE(MONTH(B9),"Jan","Feb","Mar","Apr","Mei","Jun","Jul","Agu","Sep","Okt","Nov","Des")&" "&YEAR(B9)&" (rata-rata 30 hari)") | C11: Otomatis dari posisi_data.
A12: konteks | C12: Satu kalimat konteks risiko utama saat ini (mis. keandalan pasokan gas hulu, jadwal turnaround).
A13: dosis_urea_kg_per_ha | C13: Dosis urea per hektare sesuai rekomendasi yang berlaku.
A14: dosis_npk_kg_per_ha | C14: Dosis NPK per hektare sesuai rekomendasi yang berlaku.
A15: produk_npk | C15: Nama & formula NPK utama, mis. NPK 15-15-15.
A16: status_data | B16: ASLI | C16: Biarkan "ASLI". Kata DUMMY di sel ini membuat dashboard memasang pita DATA DUMMY.

Sheet harian_gas
A1: tanggal | B1: jenis | C1: pemasok | D1: kontrak_bbtud | E1: pasokan_bbtud
A2: 46023 | B2: =IF(A2="","",IF(A2<=profil!$B$9,"Realisasi","Rencana")) -> Rencana | C2: Pemasok Gas A · Blok Hulu 4 | D2: =IFERROR(INDEX(sumber_pasokan!$E:$E,MATCH(C2,sumber_pasokan!$B:$B,0)),"") -> 0
A3: 46023 | B3: =IF(A3="","",IF(A3<=profil!$B$9,"Realisasi","Rencana")) -> Rencana | C3: Pemasok Gas B · LNG Regasifikasi | D3: =IFERROR(INDEX(sumber_pasokan!$E:$E,MATCH(C3,sumber_pasokan!$B:$B,0)),"") -> 0
A4: 46024 | B4: =IF(A4="","",IF(A4<=profil!$B$9,"Realisasi","Rencana")) -> Rencana | C4: Pemasok Gas A · Blok Hulu 4 | D4: =IFERROR(INDEX(sumber_pasokan!$E:$E,MATCH(C4,sumber_pasokan!$B:$B,0)),"") -> 0
A5: 46024 | B5: =IF(A5="","",IF(A5<=profil!$B$9,"Realisasi","Rencana")) -> Rencana | C5: Pemasok Gas B · LNG Regasifikasi | D5: =IFERROR(INDEX(sumber_pasokan!$E:$E,MATCH(C5,sumber_pasokan!$B:$B,0)),"") -> 0
A6: 46025 | B6: =IF(A6="","",IF(A6<=profil!$B$9,"Realisasi","Rencana")) -> Rencana | C6: Pemasok Gas A · Blok Hulu 4 | D6: =IFERROR(INDEX(sumber_pasokan!$E:$E,MATCH(C6,sumber_pasokan!$B:$B,0)),"") -> 0
A7: 46025 | B7: =IF(A7="","",IF(A7<=profil!$B$9,"Realisasi","Rencana")) -> Rencana | C7: Pemasok Gas B · LNG Regasifikasi | D7: =IFERROR(INDEX(sumber_pasokan!$E:$E,MATCH(C7,sumber_pasokan!$B:$B,0)),"") -> 0
A8: 46026 | B8: =IF(A8="","",IF(A8<=profil!$B$9,"Realisasi","Rencana")) -> Rencana | C8: Pemasok Gas A · Blok Hulu 4 | D8: =IFERROR(INDEX(sumber_pasokan!$E:$E,MATCH(C8,sumber_pasokan!$B:$B,0)),"") -> 0
A9: 46026 | B9: =IF(A9="","",IF(A9<=profil!$B$9,"Realisasi","Rencana")) -> Rencana | C9: Pemasok Gas B · LNG Regasifikasi | D9: =IFERROR(INDEX(sumber_pasokan!$E:$E,MATCH(C9,sumber_pasokan!$B:$B,0)),"") -> 0
A10: 46027 | B10: =IF(A10="","",IF(A10<=profil!$B$9,"Realisasi","Rencana")) -> Rencana | C10: Pemasok Gas A · Blok Hulu 4 | D10: =IFERROR(INDEX(sumber_pasokan!$E:$E,MATCH(C10,sumber_pasokan!$B:$B,0)),"") -> 0
A11: 46027 | B11: =IF(A11="","",IF(A11<=profil!$B$9,"Realisasi","Rencana")) -> Rencana | C11: Pemasok Gas B · LNG Regasifikasi | D11: =IFERROR(INDEX(sumber_pasokan!$E:$E,MATCH(C11,sumber_pasokan!$B:$B,0)),"") -> 0
A12: 46028 | B12: =IF(A12="","",IF(A12<=profil!$B$9,"Realisasi","Rencana")) -> Rencana | C12: Pemasok Gas A · Blok Hulu 4 | D12: =IFERROR(INDEX(sumber_pasokan!$E:$E,MATCH(C12,sumber_pasokan!$B:$B,0)),"") -> 0
A13: 46028 | B13: =IF(A13="","",IF(A13<=profil!$B$9,"Realisasi","Rencana")) -> Rencana | C13: Pemasok Gas B · LNG Regasifikasi | D13: =IFERROR(INDEX(sumber_pasokan!$E:$E,MATCH(C13,sumber_pasokan!$B:$B,0)),"") -> 0
... A731: 46387 | B731: =IF(A731="","",IF(A731<=profil!$B$9,"Realisasi","Rencana")) -> Rencana | C731: Pemasok Gas B · LNG Regasifikasi | D731: =IFERROR(INDEX(sumber_pasokan!$E:$E,MATCH(C731,sumber_pasokan!$B:$B,0)),"") -> 0

Sheet ringkasan_gas
A1: tanggal | B1: jenis | C1: kontrak_total_bbtud | D1: pasokan_total_bbtud | E1: kebutuhan_rencana_bbtud | F1: pemakaian_aktual_bbtud | G1: gas_per_ton_amoniak_mmbtu | H1: gas_per_ton_urea_mmbtu
A2: 46023 | B2: =IF(A2="","",IF(A2<=profil!$B$9,"Realisasi","Rencana")) -> Rencana | C2: =SUMIFS(harian_gas!$D:$D,harian_gas!$A:$A,A2) -> 0 | D2: =SUMIFS(harian_gas!$E:$E,harian_gas!$A:$A,A2) -> 0
A3: 46024 | B3: =IF(A3="","",IF(A3<=profil!$B$9,"Realisasi","Rencana")) -> Rencana | C3: =SUMIFS(harian_gas!$D:$D,harian_gas!$A:$A,A3) -> 0 | D3: =SUMIFS(harian_gas!$E:$E,harian_gas!$A:$A,A3) -> 0
A4: 46025 | B4: =IF(A4="","",IF(A4<=profil!$B$9,"Realisasi","Rencana")) -> Rencana | C4: =SUMIFS(harian_gas!$D:$D,harian_gas!$A:$A,A4) -> 0 | D4: =SUMIFS(harian_gas!$E:$E,harian_gas!$A:$A,A4) -> 0
A5: 46026 | B5: =IF(A5="","",IF(A5<=profil!$B$9,"Realisasi","Rencana")) -> Rencana | C5: =SUMIFS(harian_gas!$D:$D,harian_gas!$A:$A,A5) -> 0 | D5: =SUMIFS(harian_gas!$E:$E,harian_gas!$A:$A,A5) -> 0
A6: 46027 | B6: =IF(A6="","",IF(A6<=profil!$B$9,"Realisasi","Rencana")) -> Rencana | C6: =SUMIFS(harian_gas!$D:$D,harian_gas!$A:$A,A6) -> 0 | D6: =SUMIFS(harian_gas!$E:$E,harian_gas!$A:$A,A6) -> 0
A7: 46028 | B7: =IF(A7="","",IF(A7<=profil!$B$9,"Realisasi","Rencana")) -> Rencana | C7: =SUMIFS(harian_gas!$D:$D,harian_gas!$A:$A,A7) -> 0 | D7: =SUMIFS(harian_gas!$E:$E,harian_gas!$A:$A,A7) -> 0
A8: 46029 | B8: =IF(A8="","",IF(A8<=profil!$B$9,"Realisasi","Rencana")) -> Rencana | C8: =SUMIFS(harian_gas!$D:$D,harian_gas!$A:$A,A8) -> 0 | D8: =SUMIFS(harian_gas!$E:$E,harian_gas!$A:$A,A8) -> 0
A9: 46030 | B9: =IF(A9="","",IF(A9<=profil!$B$9,"Realisasi","Rencana")) -> Rencana | C9: =SUMIFS(harian_gas!$D:$D,harian_gas!$A:$A,A9) -> 0 | D9: =SUMIFS(harian_gas!$E:$E,harian_gas!$A:$A,A9) -> 0
A10: 46031 | B10: =IF(A10="","",IF(A10<=profil!$B$9,"Realisasi","Rencana")) -> Rencana | C10: =SUMIFS(harian_gas!$D:$D,harian_gas!$A:$A,A10) -> 0 | D10: =SUMIFS(harian_gas!$E:$E,harian_gas!$A:$A,A10) -> 0
A11: 46032 | B11: =IF(A11="","",IF(A11<=profil!$B$9,"Realisasi","Rencana")) -> Rencana | C11: =SUMIFS(harian_gas!$D:$D,harian_gas!$A:$A,A11) -> 0 | D11: =SUMIFS(harian_gas!$E:$E,harian_gas!$A:$A,A11) -> 0
A12: 46033 | B12: =IF(A12="","",IF(A12<=profil!$B$9,"Realisasi","Rencana")) -> Rencana | C12: =SUMIFS(harian_gas!$D:$D,harian_gas!$A:$A,A12) -> 0 | D12: =SUMIFS(harian_gas!$E:$E,harian_gas!$A:$A,A12) -> 0
A13: 46034 | B13: =IF(A13="","",IF(A13<=profil!$B$9,"Realisasi","Rencana")) -> Rencana | C13: =SUMIFS(harian_gas!$D:$D,harian_gas!$A:$A,A13) -> 0 | D13: =SUMIFS(harian_gas!$E:$E,harian_gas!$A:$A,A13) -> 0
... A366: 46387 | B366: =IF(A366="","",IF(A366<=profil!$B$9,"Realisasi","Rencana")) -> Rencana | C366: =SUMIFS(harian_gas!$D:$D,harian_gas!$A:$A,A366) -> 0 | D366: =SUMIFS(harian_gas!$E:$E,harian_gas!$A:$A,A366) -> 0

Sheet harian_bahan_baku
A1: tanggal | B1: jenis | C1: kode_material | D1: material | E1: stok_awal_t | F1: kedatangan_t | G1: produksi_sendiri_t | H1: pemakaian_t | I1: dijual_transfer_t | J1: stok_akhir_t | K1: cek_selisih_t
A2: 46023 | B2: =IF(A2="","",IF(A2<=profil!$B$9,"Realisasi","Rencana")) -> Rencana | C2: NH3 | D2: Amoniak | J2: =E2+F2+G2-H2-I2 -> 0 | K2: =ROUND(E2+F2+G2-H2-I2-J2,1) -> 0
A3: 46024 | B3: =IF(A3="","",IF(A3<=profil!$B$9,"Realisasi","Rencana")) -> Rencana | C3: NH3 | D3: Amoniak | E3: =J2 -> 0 | J3: =E3+F3+G3-H3-I3 -> 0 | K3: =ROUND(E3+F3+G3-H3-I3-J3,1) -> 0
A4: 46025 | B4: =IF(A4="","",IF(A4<=profil!$B$9,"Realisasi","Rencana")) -> Rencana | C4: NH3 | D4: Amoniak | E4: =J3 -> 0 | J4: =E4+F4+G4-H4-I4 -> 0 | K4: =ROUND(E4+F4+G4-H4-I4-J4,1) -> 0
A5: 46026 | B5: =IF(A5="","",IF(A5<=profil!$B$9,"Realisasi","Rencana")) -> Rencana | C5: NH3 | D5: Amoniak | E5: =J4 -> 0 | J5: =E5+F5+G5-H5-I5 -> 0 | K5: =ROUND(E5+F5+G5-H5-I5-J5,1) -> 0
A6: 46027 | B6: =IF(A6="","",IF(A6<=profil!$B$9,"Realisasi","Rencana")) -> Rencana | C6: NH3 | D6: Amoniak | E6: =J5 -> 0 | J6: =E6+F6+G6-H6-I6 -> 0 | K6: =ROUND(E6+F6+G6-H6-I6-J6,1) -> 0
A7: 46028 | B7: =IF(A7="","",IF(A7<=profil!$B$9,"Realisasi","Rencana")) -> Rencana | C7: NH3 | D7: Amoniak | E7: =J6 -> 0 | J7: =E7+F7+G7-H7-I7 -> 0 | K7: =ROUND(E7+F7+G7-H7-I7-J7,1) -> 0
A8: 46029 | B8: =IF(A8="","",IF(A8<=profil!$B$9,"Realisasi","Rencana")) -> Rencana | C8: NH3 | D8: Amoniak | E8: =J7 -> 0 | J8: =E8+F8+G8-H8-I8 -> 0 | K8: =ROUND(E8+F8+G8-H8-I8-J8,1) -> 0
A9: 46030 | B9: =IF(A9="","",IF(A9<=profil!$B$9,"Realisasi","Rencana")) -> Rencana | C9: NH3 | D9: Amoniak | E9: =J8 -> 0 | J9: =E9+F9+G9-H9-I9 -> 0 | K9: =ROUND(E9+F9+G9-H9-I9-J9,1) -> 0
A10: 46031 | B10: =IF(A10="","",IF(A10<=profil!$B$9,"Realisasi","Rencana")) -> Rencana | C10: NH3 | D10: Amoniak | E10: =J9 -> 0 | J10: =E10+F10+G10-H10-I10 -> 0 | K10: =ROUND(E10+F10+G10-H10-I10-J10,1) -> 0
A11: 46032 | B11: =IF(A11="","",IF(A11<=profil!$B$9,"Realisasi","Rencana")) -> Rencana | C11: NH3 | D11: Amoniak | E11: =J10 -> 0 | J11: =E11+F11+G11-H11-I11 -> 0 | K11: =ROUND(E11+F11+G11-H11-I11-J11,1) -> 0
A12: 46033 | B12: =IF(A12="","",IF(A12<=profil!$B$9,"Realisasi","Rencana")) -> Rencana | C12: NH3 | D12: Amoniak | E12: =J11 -> 0 | J12: =E12+F12+G12-H12-I12 -> 0 | K12: =ROUND(E12+F12+G12-H12-I12-J12,1) -> 0
A13: 46034 | B13: =IF(A13="","",IF(A13<=profil!$B$9,"Realisasi","Rencana")) -> Rencana | C13: NH3 | D13: Amoniak | E13: =J12 -> 0 | J13: =E13+F13+G13-H13-I13 -> 0 | K13: =ROUND(E13+F13+G13-H13-I13-J13,1) -> 0
A14: 46035 | B14: =IF(A14="","",IF(A14<=profil!$B$9,"Realisasi","Rencana")) -> Rencana | C14: NH3 | D14: Amoniak | E14: =J13 -> 0 | J14: =E14+F14+G14-H14-I14 -> 0 | K14: =ROUND(E14+F14+G14-H14-I14-J14,1) -> 0
... A366: 46387 | B366: =IF(A366="","",IF(A366<=profil!$B$9,"Realisasi","Rencana")) -> Rencana | C366: NH3 | D366: Amoniak | E366: =J365 -> 0 | J366: =E366+F366+G366-H366-I366 -> 0 | K366: =ROUND(E366+F366+G366-H366-I366-J366,1) -> 0
A367: 46023 | B367: =IF(A367="","",IF(A367<=profil!$B$9,"Realisasi","Rencana")) -> Rencana | C367: KCL | D367: KCl | G367: 0 | J367: =E367+F367+G367-H367-I367 -> 0 | K367: =ROUND(E367+F367+G367-H367-I367-J367,1) -> 0
A368: 46024 | B368: =IF(A368="","",IF(A368<=profil!$B$9,"Realisasi","Rencana")) -> Rencana | C368: KCL | D368: KCl | E368: =J367 -> 0 | G368: 0 | J368: =E368+F368+G368-H368-I368 -> 0 | K368: =ROUND(E368+F368+G368-H368-I368-J368,1) -> 0
A369: 46025 | B369: =IF(A369="","",IF(A369<=profil!$B$9,"Realisasi","Rencana")) -> Rencana | C369: KCL | D369: KCl | E369: =J368 -> 0 | G369: 0 | J369: =E369+F369+G369-H369-I369 -> 0 | K369: =ROUND(E369+F369+G369-H369-I369-J369,1) -> 0
A370: 46026 | B370: =IF(A370="","",IF(A370<=profil!$B$9,"Realisasi","Rencana")) -> Rencana | C370: KCL | D370: KCl | E370: =J369 -> 0 | G370: 0 | J370: =E370+F370+G370-H370-I370 -> 0 | K370: =ROUND(E370+F370+G370-H370-I370-J370,1) -> 0
A371: 46027 | B371: =IF(A371="","",IF(A371<=profil!$B$9,"Realisasi","Rencana")) -> Rencana | C371: KCL | D371: KCl | E371: =J370 -> 0 | G371: 0 | J371: =E371+F371+G371-H371-I371 -> 0 | K371: =ROUND(E371+F371+G371-H371-I371-J371,1) -> 0
A372: 46028 | B372: =IF(A372="","",IF(A372<=profil!$B$9,"Realisasi","Rencana")) -> Rencana | C372: KCL | D372: KCl | E372: =J371 -> 0 | G372: 0 | J372: =E372+F372+G372-H372-I372 -> 0 | K372: =ROUND(E372+F372+G372-H372-I372-J372,1) -> 0
A373: 46029 | B373: =IF(A373="","",IF(A373<=profil!$B$9,"Realisasi","Rencana")) -> Rencana | C373: KCL | D373: KCl | E373: =J372 -> 0 | G373: 0 | J373: =E373+F373+G373-H373-I373 -> 0 | K373: =ROUND(E373+F373+G373-H373-I373-J373,1) -> 0
A374: 46030 | B374: =IF(A374="","",IF(A374<=profil!$B$9,"Realisasi","Rencana")) -> Rencana | C374: KCL | D374: KCl | E374: =J373 -> 0 | G374: 0 | J374: =E374+F374+G374-H374-I374 -> 0 | K374: =ROUND(E374+F374+G374-H374-I374-J374,1) -> 0
A375: 46031 | B375: =IF(A375="","",IF(A375<=profil!$B$9,"Realisasi","Rencana")) -> Rencana | C375: KCL | D375: KCl | E375: =J374 -> 0 | G375: 0 | J375: =E375+F375+G375-H375-I375 -> 0 | K375: =ROUND(E375+F375+G375-H375-I375-J375,1) -> 0
A376: 46032 | B376: =IF(A376="","",IF(A376<=profil!$B$9,"Realisasi","Rencana")) -> Rencana | C376: KCL | D376: KCl | E376: =J375 -> 0 | G376: 0 | J376: =E376+F376+G376-H376-I376 -> 0 | K376: =ROUND(E376+F376+G376-H376-I376-J376,1) -> 0
A377: 46033 | B377: =IF(A377="","",IF(A377<=profil!$B$9,"Realisasi","Rencana")) -> Rencana | C377: KCL | D377: KCl | E377: =J376 -> 0 | G377: 0 | J377: =E377+F377+G377-H377-I377 -> 0 | K377: =ROUND(E377+F377+G377-H377-I377-J377,1) -> 0
A378: 46034 | B378: =IF(A378="","",IF(A378<=profil!$B$9,"Realisasi","Rencana")) -> Rencana | C378: KCL | D378: KCl | E378: =J377 -> 0 | G378: 0 | J378: =E378+F378+G378-H378-I378 -> 0 | K378: =ROUND(E378+F378+G378-H378-I378-J378,1) -> 0
A379: 46035 | B379: =IF(A379="","",IF(A379<=profil!$B$9,"Realisasi","Rencana")) -> Rencana | C379: KCL | D379: KCl | E379: =J378 -> 0 | G379: 0 | J379: =E379+F379+G379-H379-I379 -> 0 | K379: =ROUND(E379+F379+G379-H379-I379-J379,1) -> 0
... A731: 46387 | B731: =IF(A731="","",IF(A731<=profil!$B$9,"Realisasi","Rencana")) -> Rencana | C731: KCL | D731: KCl | E731: =J730 -> 0 | G731: 0 | J731: =E731+F731+G731-H731-I731 -> 0 | K731: =ROUND(E731+F731+G731-H731-I731-J731,1) -> 0
A732: 46023 | B732: =IF(A732="","",IF(A732<=profil!$B$9,"Realisasi","Rencana")) -> Rencana | C732: DAP | D732: DAP | G732: 0 | J732: =E732+F732+G732-H732-I732 -> 0 | K732: =ROUND(E732+F732+G732-H732-I732-J732,1) -> 0
A733: 46024 | B733: =IF(A733="","",IF(A733<=profil!$B$9,"Realisasi","Rencana")) -> Rencana | C733: DAP | D733: DAP | E733: =J732 -> 0 | G733: 0 | J733: =E733+F733+G733-H733-I733 -> 0 | K733: =ROUND(E733+F733+G733-H733-I733-J733,1) -> 0
A734: 46025 | B734: =IF(A734="","",IF(A734<=profil!$B$9,"Realisasi","Rencana")) -> Rencana | C734: DAP | D734: DAP | E734: =J733 -> 0 | G734: 0 | J734: =E734+F734+G734-H734-I734 -> 0 | K734: =ROUND(E734+F734+G734-H734-I734-J734,1) -> 0
A735: 46026 | B735: =IF(A735="","",IF(A735<=profil!$B$9,"Realisasi","Rencana")) -> Rencana | C735: DAP | D735: DAP | E735: =J734 -> 0 | G735: 0 | J735: =E735+F735+G735-H735-I735 -> 0 | K735: =ROUND(E735+F735+G735-H735-I735-J735,1) -> 0
A736: 46027 | B736: =IF(A736="","",IF(A736<=profil!$B$9,"Realisasi","Rencana")) -> Rencana | C736: DAP | D736: DAP | E736: =J735 -> 0 | G736: 0 | J736: =E736+F736+G736-H736-I736 -> 0 | K736: =ROUND(E736+F736+G736-H736-I736-J736,1) -> 0
A737: 46028 | B737: =IF(A737="","",IF(A737<=profil!$B$9,"Realisasi","Rencana")) -> Rencana | C737: DAP | D737: DAP | E737: =J736 -> 0 | G737: 0 | J737: =E737+F737+G737-H737-I737 -> 0 | K737: =ROUND(E737+F737+G737-H737-I737-J737,1) -> 0
A738: 46029 | B738: =IF(A738="","",IF(A738<=profil!$B$9,"Realisasi","Rencana")) -> Rencana | C738: DAP | D738: DAP | E738: =J737 -> 0 | G738: 0 | J738: =E738+F738+G738-H738-I738 -> 0 | K738: =ROUND(E738+F738+G738-H738-I738-J738,1) -> 0
A739: 46030 | B739: =IF(A739="","",IF(A739<=profil!$B$9,"Realisasi","Rencana")) -> Rencana | C739: DAP | D739: DAP | E739: =J738 -> 0 | G739: 0 | J739: =E739+F739+G739-H739-I739 -> 0 | K739: =ROUND(E739+F739+G739-H739-I739-J739,1) -> 0
A740: 46031 | B740: =IF(A740="","",IF(A740<=profil!$B$9,"Realisasi","Rencana")) -> Rencana | C740: DAP | D740: DAP | E740: =J739 -> 0 | G740: 0 | J740: =E740+F740+G740-H740-I740 -> 0 | K740: =ROUND(E740+F740+G740-H740-I740-J740,1) -> 0
A741: 46032 | B741: =IF(A741="","",IF(A741<=profil!$B$9,"Realisasi","Rencana")) -> Rencana | C741: DAP | D741: DAP | E741: =J740 -> 0 | G741: 0 | J741: =E741+F741+G741-H741-I741 -> 0 | K741: =ROUND(E741+F741+G741-H741-I741-J741,1) -> 0
A742: 46033 | B742: =IF(A742="","",IF(A742<=profil!$B$9,"Realisasi","Rencana")) -> Rencana | C742: DAP | D742: DAP | E742: =J741 -> 0 | G742: 0 | J742: =E742+F742+G742-H742-I742 -> 0 | K742: =ROUND(E742+F742+G742-H742-I742-J742,1) -> 0
...

Sheet harian_produksi
A1: tanggal | B1: jenis | C1: unit | D1: produk | E1: kapasitas_t_per_hari | F1: produksi_t
A2: 46023 | B2: =IF(A2="","",IF(A2<=profil!$B$9,"Realisasi","Rencana")) -> Rencana | C2: Amoniak-1 | D2: Amoniak
A3: 46024 | B3: =IF(A3="","",IF(A3<=profil!$B$9,"Realisasi","Rencana")) -> Rencana | C3: Amoniak-1 | D3: Amoniak | E3: =E2 -> 0
A4: 46025 | B4: =IF(A4="","",IF(A4<=profil!$B$9,"Realisasi","Rencana")) -> Rencana | C4: Amoniak-1 | D4: Amoniak | E4: =E3 -> 0
A5: 46026 | B5: =IF(A5="","",IF(A5<=profil!$B$9,"Realisasi","Rencana")) -> Rencana | C5: Amoniak-1 | D5: Amoniak | E5: =E4 -> 0
A6: 46027 | B6: =IF(A6="","",IF(A6<=profil!$B$9,"Realisasi","Rencana")) -> Rencana | C6: Amoniak-1 | D6: Amoniak | E6: =E5 -> 0
A7: 46028 | B7: =IF(A7="","",IF(A7<=profil!$B$9,"Realisasi","Rencana")) -> Rencana | C7: Amoniak-1 | D7: Amoniak | E7: =E6 -> 0
A8: 46029 | B8: =IF(A8="","",IF(A8<=profil!$B$9,"Realisasi","Rencana")) -> Rencana | C8: Amoniak-1 | D8: Amoniak | E8: =E7 -> 0
A9: 46030 | B9: =IF(A9="","",IF(A9<=profil!$B$9,"Realisasi","Rencana")) -> Rencana | C9: Amoniak-1 | D9: Amoniak | E9: =E8 -> 0
A10: 46031 | B10: =IF(A10="","",IF(A10<=profil!$B$9,"Realisasi","Rencana")) -> Rencana | C10: Amoniak-1 | D10: Amoniak | E10: =E9 -> 0
A11: 46032 | B11: =IF(A11="","",IF(A11<=profil!$B$9,"Realisasi","Rencana")) -> Rencana | C11: Amoniak-1 | D11: Amoniak | E11: =E10 -> 0
A12: 46033 | B12: =IF(A12="","",IF(A12<=profil!$B$9,"Realisasi","Rencana")) -> Rencana | C12: Amoniak-1 | D12: Amoniak | E12: =E11 -> 0
A13: 46034 | B13: =IF(A13="","",IF(A13<=profil!$B$9,"Realisasi","Rencana")) -> Rencana | C13: Amoniak-1 | D13: Amoniak | E13: =E12 -> 0
A14: 46035 | B14: =IF(A14="","",IF(A14<=profil!$B$9,"Realisasi","Rencana")) -> Rencana | C14: Amoniak-1 | D14: Amoniak | E14: =E13 -> 0
... A366: 46387 | B366: =IF(A366="","",IF(A366<=profil!$B$9,"Realisasi","Rencana")) -> Rencana | C366: Amoniak-1 | D366: Amoniak | E366: =E365 -> 0
A367: 46023 | B367: =IF(A367="","",IF(A367<=profil!$B$9,"Realisasi","Rencana")) -> Rencana | C367: Urea-1 | D367: Urea
A368: 46024 | B368: =IF(A368="","",IF(A368<=profil!$B$9,"Realisasi","Rencana")) -> Rencana | C368: Urea-1 | D368: Urea | E368: =E367 -> 0
A369: 46025 | B369: =IF(A369="","",IF(A369<=profil!$B$9,"Realisasi","Rencana")) -> Rencana | C369: Urea-1 | D369: Urea | E369: =E368 -> 0
A370: 46026 | B370: =IF(A370="","",IF(A370<=profil!$B$9,"Realisasi","Rencana")) -> Rencana | C370: Urea-1 | D370: Urea | E370: =E369 -> 0
A371: 46027 | B371: =IF(A371="","",IF(A371<=profil!$B$9,"Realisasi","Rencana")) -> Rencana | C371: Urea-1 | D371: Urea | E371: =E370 -> 0
A372: 46028 | B372: =IF(A372="","",IF(A372<=profil!$B$9,"Realisasi","Rencana")) -> Rencana | C372: Urea-1 | D372: Urea | E372: =E371 -> 0
A373: 46029 | B373: =IF(A373="","",IF(A373<=profil!$B$9,"Realisasi","Rencana")) -> Rencana | C373: Urea-1 | D373: Urea | E373: =E372 -> 0
A374: 46030 | B374: =IF(A374="","",IF(A374<=profil!$B$9,"Realisasi","Rencana")) -> Rencana | C374: Urea-1 | D374: Urea | E374: =E373 -> 0
A375: 46031 | B375: =IF(A375="","",IF(A375<=profil!$B$9,"Realisasi","Rencana")) -> Rencana | C375: Urea-1 | D375: Urea | E375: =E374 -> 0
A376: 46032 | B376: =IF(A376="","",IF(A376<=profil!$B$9,"Realisasi","Rencana")) -> Rencana | C376: Urea-1 | D376: Urea | E376: =E375 -> 0
A377: 46033 | B377: =IF(A377="","",IF(A377<=profil!$B$9,"Realisasi","Rencana")) -> Rencana | C377: Urea-1 | D377: Urea | E377: =E376 -> 0
A378: 46034 | B378: =IF(A378="","",IF(A378<=profil!$B$9,"Realisasi","Rencana")) -> Rencana | C378: Urea-1 | D378: Urea | E378: =E377 -> 0
A379: 46035 | B379: =IF(A379="","",IF(A379<=profil!$B$9,"Realisasi","Rencana")) -> Rencana | C379: Urea-1 | D379: Urea | E379: =E378 -> 0
... A731: 46387 | B731: =IF(A731="","",IF(A731<=profil!$B$9,"Realisasi","Rencana")) -> Rencana | C731: Urea-1 | D731: Urea | E731: =E730 -> 0
A732: 46023 | B732: =IF(A732="","",IF(A732<=profil!$B$9,"Realisasi","Rencana")) -> Rencana | C732: NPK-1 | D732: NPK
A733: 46024 | B733: =IF(A733="","",IF(A733<=profil!$B$9,"Realisasi","Rencana")) -> Rencana | C733: NPK-1 | D733: NPK | E733: =E732 -> 0
A734: 46025 | B734: =IF(A734="","",IF(A734<=profil!$B$9,"Realisasi","Rencana")) -> Rencana | C734: NPK-1 | D734: NPK | E734: =E733 -> 0
A735: 46026 | B735: =IF(A735="","",IF(A735<=profil!$B$9,"Realisasi","Rencana")) -> Rencana | C735: NPK-1 | D735: NPK | E735: =E734 -> 0
A736: 46027 | B736: =IF(A736="","",IF(A736<=profil!$B$9,"Realisasi","Rencana")) -> Rencana | C736: NPK-1 | D736: NPK | E736: =E735 -> 0
A737: 46028 | B737: =IF(A737="","",IF(A737<=profil!$B$9,"Realisasi","Rencana")) -> Rencana | C737: NPK-1 | D737: NPK | E737: =E736 -> 0
A738: 46029 | B738: =IF(A738="","",IF(A738<=profil!$B$9,"Realisasi","Rencana")) -> Rencana | C738: NPK-1 | D738: NPK | E738: =E737 -> 0
A739: 46030 | B739: =IF(A739="","",IF(A739<=profil!$B$9,"Realisasi","Rencana")) -> Rencana | C739: NPK-1 | D739: NPK | E739: =E738 -> 0
A740: 46031 | B740: =IF(A740="","",IF(A740<=profil!$B$9,"Realisasi","Rencana")) -> Rencana | C740: NPK-1 | D740: NPK | E740: =E739 -> 0
A741: 46032 | B741: =IF(A741="","",IF(A741<=profil!$B$9,"Realisasi","Rencana")) -> Rencana | C741: NPK-1 | D741: NPK | E741: =E740 -> 0
A742: 46033 | B742: =IF(A742="","",IF(A742<=profil!$B$9,"Realisasi","Rencana")) -> Rencana | C742: NPK-1 | D742: NPK | E742: =E741 -> 0
...

Sheet rkap_bulanan
A1: unit | B1: produk | C1: jan | D1: feb | E1: mar | F1: apr | G1: mei | H1: jun | I1: jul | J1: agu | K1: sep | L1: okt | M1: nov | N1: des | O1: total_2026
A2: Amoniak-1 | B2: Amoniak | O2: =SUM(C2:N2) -> 0
A3: Urea-1 | B3: Urea | O3: =SUM(C3:N3) -> 0
A4: NPK-1 | B4: NPK | O4: =SUM(C4:N4) -> 0

Sheet stok_produk_lini1
A1: tanggal | B1: jenis | C1: produk | D1: stok_awal_t | E1: masuk_t | F1: penyaluran_t | G1: stok_akhir_t | H1: curah_di_pabrik_t | I1: cek_selisih_t
A2: 46023 | B2: =IF(A2="","",IF(A2<=profil!$B$9,"Realisasi","Rencana")) -> Rencana | C2: Urea | G2: =D2+E2-F2 -> 0 | I2: =ROUND(D2+E2-F2-G2,1) -> 0
A3: 46024 | B3: =IF(A3="","",IF(A3<=profil!$B$9,"Realisasi","Rencana")) -> Rencana | C3: Urea | D3: =G2 -> 0 | G3: =D3+E3-F3 -> 0 | I3: =ROUND(D3+E3-F3-G3,1) -> 0
A4: 46025 | B4: =IF(A4="","",IF(A4<=profil!$B$9,"Realisasi","Rencana")) -> Rencana | C4: Urea | D4: =G3 -> 0 | G4: =D4+E4-F4 -> 0 | I4: =ROUND(D4+E4-F4-G4,1) -> 0
A5: 46026 | B5: =IF(A5="","",IF(A5<=profil!$B$9,"Realisasi","Rencana")) -> Rencana | C5: Urea | D5: =G4 -> 0 | G5: =D5+E5-F5 -> 0 | I5: =ROUND(D5+E5-F5-G5,1) -> 0
A6: 46027 | B6: =IF(A6="","",IF(A6<=profil!$B$9,"Realisasi","Rencana")) -> Rencana | C6: Urea | D6: =G5 -> 0 | G6: =D6+E6-F6 -> 0 | I6: =ROUND(D6+E6-F6-G6,1) -> 0
A7: 46028 | B7: =IF(A7="","",IF(A7<=profil!$B$9,"Realisasi","Rencana")) -> Rencana | C7: Urea | D7: =G6 -> 0 | G7: =D7+E7-F7 -> 0 | I7: =ROUND(D7+E7-F7-G7,1) -> 0
A8: 46029 | B8: =IF(A8="","",IF(A8<=profil!$B$9,"Realisasi","Rencana")) -> Rencana | C8: Urea | D8: =G7 -> 0 | G8: =D8+E8-F8 -> 0 | I8: =ROUND(D8+E8-F8-G8,1) -> 0
A9: 46030 | B9: =IF(A9="","",IF(A9<=profil!$B$9,"Realisasi","Rencana")) -> Rencana | C9: Urea | D9: =G8 -> 0 | G9: =D9+E9-F9 -> 0 | I9: =ROUND(D9+E9-F9-G9,1) -> 0
A10: 46031 | B10: =IF(A10="","",IF(A10<=profil!$B$9,"Realisasi","Rencana")) -> Rencana | C10: Urea | D10: =G9 -> 0 | G10: =D10+E10-F10 -> 0 | I10: =ROUND(D10+E10-F10-G10,1) -> 0
A11: 46032 | B11: =IF(A11="","",IF(A11<=profil!$B$9,"Realisasi","Rencana")) -> Rencana | C11: Urea | D11: =G10 -> 0 | G11: =D11+E11-F11 -> 0 | I11: =ROUND(D11+E11-F11-G11,1) -> 0
A12: 46033 | B12: =IF(A12="","",IF(A12<=profil!$B$9,"Realisasi","Rencana")) -> Rencana | C12: Urea | D12: =G11 -> 0 | G12: =D12+E12-F12 -> 0 | I12: =ROUND(D12+E12-F12-G12,1) -> 0
A13: 46034 | B13: =IF(A13="","",IF(A13<=profil!$B$9,"Realisasi","Rencana")) -> Rencana | C13: Urea | D13: =G12 -> 0 | G13: =D13+E13-F13 -> 0 | I13: =ROUND(D13+E13-F13-G13,1) -> 0
A14: 46035 | B14: =IF(A14="","",IF(A14<=profil!$B$9,"Realisasi","Rencana")) -> Rencana | C14: Urea | D14: =G13 -> 0 | G14: =D14+E14-F14 -> 0 | I14: =ROUND(D14+E14-F14-G14,1) -> 0
... A366: 46387 | B366: =IF(A366="","",IF(A366<=profil!$B$9,"Realisasi","Rencana")) -> Rencana | C366: Urea | D366: =G365 -> 0 | G366: =D366+E366-F366 -> 0 | I366: =ROUND(D366+E366-F366-G366,1) -> 0
A367: 46023 | B367: =IF(A367="","",IF(A367<=profil!$B$9,"Realisasi","Rencana")) -> Rencana | C367: NPK | G367: =D367+E367-F367 -> 0 | I367: =ROUND(D367+E367-F367-G367,1) -> 0
A368: 46024 | B368: =IF(A368="","",IF(A368<=profil!$B$9,"Realisasi","Rencana")) -> Rencana | C368: NPK | D368: =G367 -> 0 | G368: =D368+E368-F368 -> 0 | I368: =ROUND(D368+E368-F368-G368,1) -> 0
A369: 46025 | B369: =IF(A369="","",IF(A369<=profil!$B$9,"Realisasi","Rencana")) -> Rencana | C369: NPK | D369: =G368 -> 0 | G369: =D369+E369-F369 -> 0 | I369: =ROUND(D369+E369-F369-G369,1) -> 0
A370: 46026 | B370: =IF(A370="","",IF(A370<=profil!$B$9,"Realisasi","Rencana")) -> Rencana | C370: NPK | D370: =G369 -> 0 | G370: =D370+E370-F370 -> 0 | I370: =ROUND(D370+E370-F370-G370,1) -> 0
A371: 46027 | B371: =IF(A371="","",IF(A371<=profil!$B$9,"Realisasi","Rencana")) -> Rencana | C371: NPK | D371: =G370 -> 0 | G371: =D371+E371-F371 -> 0 | I371: =ROUND(D371+E371-F371-G371,1) -> 0
A372: 46028 | B372: =IF(A372="","",IF(A372<=profil!$B$9,"Realisasi","Rencana")) -> Rencana | C372: NPK | D372: =G371 -> 0 | G372: =D372+E372-F372 -> 0 | I372: =ROUND(D372+E372-F372-G372,1) -> 0
A373: 46029 | B373: =IF(A373="","",IF(A373<=profil!$B$9,"Realisasi","Rencana")) -> Rencana | C373: NPK | D373: =G372 -> 0 | G373: =D373+E373-F373 -> 0 | I373: =ROUND(D373+E373-F373-G373,1) -> 0
A374: 46030 | B374: =IF(A374="","",IF(A374<=profil!$B$9,"Realisasi","Rencana")) -> Rencana | C374: NPK | D374: =G373 -> 0 | G374: =D374+E374-F374 -> 0 | I374: =ROUND(D374+E374-F374-G374,1) -> 0
A375: 46031 | B375: =IF(A375="","",IF(A375<=profil!$B$9,"Realisasi","Rencana")) -> Rencana | C375: NPK | D375: =G374 -> 0 | G375: =D375+E375-F375 -> 0 | I375: =ROUND(D375+E375-F375-G375,1) -> 0
A376: 46032 | B376: =IF(A376="","",IF(A376<=profil!$B$9,"Realisasi","Rencana")) -> Rencana | C376: NPK | D376: =G375 -> 0 | G376: =D376+E376-F376 -> 0 | I376: =ROUND(D376+E376-F376-G376,1) -> 0
A377: 46033 | B377: =IF(A377="","",IF(A377<=profil!$B$9,"Realisasi","Rencana")) -> Rencana | C377: NPK | D377: =G376 -> 0 | G377: =D377+E377-F377 -> 0 | I377: =ROUND(D377+E377-F377-G377,1) -> 0
A378: 46034 | B378: =IF(A378="","",IF(A378<=profil!$B$9,"Realisasi","Rencana")) -> Rencana | C378: NPK | D378: =G377 -> 0 | G378: =D378+E378-F378 -> 0 | I378: =ROUND(D378+E378-F378-G378,1) -> 0
A379: 46035 | B379: =IF(A379="","",IF(A379<=profil!$B$9,"Realisasi","Rencana")) -> Rencana | C379: NPK | D379: =G378 -> 0 | G379: =D379+E379-F379 -> 0 | I379: =ROUND(D379+E379-F379-G379,1) -> 0
... A731: 46387 | B731: =IF(A731="","",IF(A731<=profil!$B$9,"Realisasi","Rencana")) -> Rencana | C731: NPK | D731: =G730 -> 0 | G731: =D731+E731-F731 -> 0 | I731: =ROUND(D731+E731-F731-G731,1) -> 0

Sheet jadwal_kapal
A1: material | B1: negara_asal | C1: pelabuhan_muat | D1: nama_kapal | E1: volume_t | F1: eta_terkini | G1: eta_awal | H1: status | I1: jarak_nm | J1: waktu_layar_hari | K1: lewat_hormuz | L1: catatan
J2: =IF(I2="","",ROUND(I2/(12.5*24),1))
J3: =IF(I3="","",ROUND(I3/(12.5*24),1))
J4: =IF(I4="","",ROUND(I4/(12.5*24),1))
J5: =IF(I5="","",ROUND(I5/(12.5*24),1))
J6: =IF(I6="","",ROUND(I6/(12.5*24),1))
J7: =IF(I7="","",ROUND(I7/(12.5*24),1))
J8: =IF(I8="","",ROUND(I8/(12.5*24),1))
J9: =IF(I9="","",ROUND(I9/(12.5*24),1))
J10: =IF(I10="","",ROUND(I10/(12.5*24),1))
J11: =IF(I11="","",ROUND(I11/(12.5*24),1))
J12: =IF(I12="","",ROUND(I12/(12.5*24),1))
J13: =IF(I13="","",ROUND(I13/(12.5*24),1))
... J61: =IF(I61="","",ROUND(I61/(12.5*24),1))

Sheet perubahan_versi
A1: versi_lama | B1: versi_baru | C1: material | D1: nama_kapal | E1: eta_lama | F1: eta_baru | G1: volume_lama_t | H1: volume_baru_t | I1: alasan

Sheet status_unit
A1: unit | B1: status | C1: mulai | D1: selesai | E1: keterangan
A2: Amoniak-1 | B2: Beroperasi
A3: Urea-1 | B3: Beroperasi
A4: NPK-1 | B4: Beroperasi

Sheet parameter_kri
A1: kode_material | B1: material | C1: sifat_pasokan | D1: satuan | E1: safety_stock | F1: deadstock | G1: ambang_aman_pct | H1: ambang_bahaya_pct | I1: nama_kri
A2: NH3 | B2: Amoniak | C2: Produksi sendiri (gas alam) | D2: ton | G2: 100 | H2: 92.25 | I2: Pemenuhan Safety Stock Amoniak (penyangga gas)
A3: KCL | B3: KCl | C3: Impor | D3: ton | G3: 100 | H3: 92.25 | I3: Pemenuhan Safety Stock Bahan Baku Non-Gas
A4: DAP | B4: DAP | C4: Impor | D4: ton | G4: 100 | H4: 92.25 | I4: Pemenuhan Safety Stock Bahan Baku Non-Gas
A5: ZA | B5: ZA | C5: Domestik (antar-entitas PI Group) | D5: ton | G5: 100 | H5: 92.25 | I5: Pemenuhan Safety Stock Bahan Baku Non-Gas
A6: CLAY | B6: Clay / filler | C6: Domestik | D6: ton | G6: 100 | H6: 92.25 | I6: Pemenuhan Safety Stock Bahan Baku Non-Gas
A7: GAS | B7: Gas alam | C7: Pipa (kontrak PJBG) | D7: BBTUD | G7: 95 | H7: 90 | I7: Pemenuhan Pasokan Gas terhadap Kebutuhan Operasi (ambang usulan, belum resmi)

Sheet cons_rate
A1: produk | B1: bahan | C1: rasio | D1: satuan
A2: Urea | B2: Amoniak | D2: ton/ton
A3: Urea | B3: Gas alam (utilitas) | D3: MMBTU/ton
A4: Amoniak | B4: Gas alam (bahan baku + bahan bakar) | D4: MMBTU/ton
A5: NPK 15-15-15 | B5: DAP | D5: ton/ton
A6: NPK 15-15-15 | B6: KCl | D6: ton/ton
A7: NPK 15-15-15 | B7: Urea (internal untuk NPK) | D7: ton/ton
A8: NPK 15-15-15 | B8: ZA | D8: ton/ton
A9: NPK 15-15-15 | B9: Clay / filler | D9: ton/ton

Sheet sumber_pasokan
A1: id | B1: nama | C1: material | D1: moda | E1: volume_acuan | F1: satuan_volume
A2: GAS-1 | B2: Pemasok Gas A · Blok Hulu 4 | C2: Gas alam | D2: Pipa | F2: BBTUD kontrak
A3: GAS-2 | B3: Pemasok Gas B · LNG Regasifikasi | C3: Gas alam | D3: Pipa | F3: BBTUD kontrak
A4: KCL-RUS | B4: Impor KCl Rusia | C4: KCl | D4: Laut | F4: ton per kargo
A5: DAP-TIO | B5: Impor DAP Tiongkok | C5: DAP | D5: Laut | F5: ton per kargo
A6: ZA-DOM | B6: Kiriman ZA Domestik · PKG | C6: ZA | D6: Laut | F6: ton per kargo
A7: CLAY-DOM | B7: Clay pemasok lokal | C7: Clay / filler | D7: Darat | F7: pengiriman mingguan

Sheet transfer_antar_entitas
A1: tanggal | B1: jenis | C1: dari | D1: ke | E1: material | F1: volume_t

Sheet ambang_siaga
A1: tingkat | B1: pemicu | C1: tindakan
A2: Siaga 1 · Pantau | B2: Pasokan gas < 95% kebutuhan selama 3 hari berturut-turut, atau KCl/DAP < 100% safety stock | C2: Rapat pasokan dua kali seminggu; konfirmasi ulang jadwal kapal dan nominasi gas.
A3: Siaga 2 · Amankan | B3: Pasokan gas < 90% selama 7 hari, atau stok amoniak < 7 hari pemakaian, atau satu kargo tertunda > 14 hari | C3: Eskalasi ke pemasok gas & SKK Migas; atur ulang beban antar-unit; aktifkan pembelian pengganti.
A4: Siaga 3 · Realokasi | B4: Pasokan gas < 80%, atau stok amoniak < 3 hari, atau KCl/DAP < deadstock | C4: Turunkan beban terencana, prioritaskan pupuk subsidi, minta realokasi produksi/transfer antar-entitas PI Group; bawa ke Direksi.
